Workbook

Sheet CURSOS
A1: ID_Curso | B1: # | C1: Nombre_Curso | D1: Temática | E1: TIPO | F1: Año | G1: Mes | H1: Total_Sesiones | I1: Inscritos | J1: %Asistencias | K1: %Reconocimientos
A2: TIE_1 | B2: =1 -> 1 | C2: NUESTRO HOGAR EN EL UNIVERSO | D2: TIERRA | E2: ASTRO | F2: 2024 | G2: JUL | H2: 4 | I2: =COUNTIF(ASISTENCIAS!$A:$A, $A2) -> 7 | J2: =IFERROR(SUMIF(ASISTENCIAS!$A:$A, $A2, ASISTENCIAS!$X:$X) / (COUNTIF(ASISTENCIAS!$A:$A, $A2) * $H2) * 100, 0) -> 32.142857 | K2: =IFERROR(COUNTIFS(ASISTENCIAS!$A:$A, $A2, ASISTENCIAS!$Y:$Y, TRUE) / COUNTIF(ASISTENCIAS!$A:$A, $A2)*100,0) -> 100
A3: LUN_1 | B3: =B2+1 -> 2 | C3: EN EL OMBLIGO DE LA LUNA | D3: LUNA | E3: ASTRO | F3: 2024 | G3: SEP | H3: 5 | I3: =COUNTIF(ASISTENCIAS!$A:$A, $A3) -> 16 | J3: =IFERROR(SUMIF(ASISTENCIAS!$A:$A, $A3, ASISTENCIAS!$X:$X) / (COUNTIF(ASISTENCIAS!$A:$A, $A3) * $H3) * 100, 0) -> 71.25 | K3: =IFERROR(COUNTIFS(ASISTENCIAS!$A:$A, $A3, ASISTENCIAS!$Y:$Y, TRUE) / COUNTIF(ASISTENCIAS!$A:$A, $A3)*100,0) -> 62.5
A4: SOL_1 | B4: =B3+1 -> 3 | C4: LA ESTRELLA QUE NOS ILUMINA | D4: SOL | E4: ASTRO | F4: 2024 | G4: OCT | H4: 5 | I4: =COUNTIF(ASISTENCIAS!$A:$A, $A4) -> 9 | J4: =IFERROR(SUMIF(ASISTENCIAS!$A:$A, $A4, ASISTENCIAS!$X:$X) / (COUNTIF(ASISTENCIAS!$A:$A, $A4) * $H4) * 100, 0) -> 62.222222 | K4: =IFERROR(COUNTIFS(ASISTENCIAS!$A:$A, $A4, ASISTENCIAS!$Y:$Y, TRUE) / COUNTIF(ASISTENCIAS!$A:$A, $A4)*100,0) -> 44.444444
A5: SS_1 | B5: =B4+1 -> 4 | C5: VAGABUNDOS DEL FIRMAMENTO | D5: SISTEMA SOLAR | E5: ASTRO | F5: 2024 | G5: OCT | H5: 5 | I5: =COUNTIF(ASISTENCIAS!$A:$A, $A5) -> 17 | J5: =IFERROR(SUMIF(ASISTENCIAS!$A:$A, $A5, ASISTENCIAS!$X:$X) / (COUNTIF(ASISTENCIAS!$A:$A, $A5) * $H5) * 100, 0) -> 69.411765 | K5: =IFERROR(COUNTIFS(ASISTENCIAS!$A:$A, $A5, ASISTENCIAS!$Y:$Y, TRUE) / COUNTIF(ASISTENCIAS!$A:$A, $A5)*100,0) -> 52.941176
A6: CON_1 | B6: =B5+1 -> 5 | C6: EL ROMPECABEZAS DEL CIELO | D6: CONSTELACIONES | E6: ASTRO | F6: 2024 | G6: NOV | H6: 5 | I6: =COUNTIF(ASISTENCIAS!$A:$A, $A6) -> 25 | J6: =IFERROR(SUMIF(ASISTENCIAS!$A:$A, $A6, ASISTENCIAS!$X:$X) / (COUNTIF(ASISTENCIAS!$A:$A, $A6) * $H6) * 100, 0) -> 56 | K6: =IFERROR(COUNTIFS(ASISTENCIAS!$A:$A, $A6, ASISTENCIAS!$Y:$Y, TRUE) / COUNTIF(ASISTENCIAS!$A:$A, $A6)*100,0) -> 52
A7: MES_1 | B7: =B6+1 -> 6 | C7: ¿CÓMO ENCONTRAR TESOROS EN EL CIELO? | D7: MESSIER | E7: ASTRO | F7: 2025 | G7: FEB | H7: 5 | I7: =COUNTIF(ASISTENCIAS!$A:$A, $A7) -> 27 | J7: =IFERROR(SUMIF(ASISTENCIAS!$A:$A, $A7, ASISTENCIAS!$X:$X) / (COUNTIF(ASISTENCIAS!$A:$A, $A7) * $H7) * 100, 0) -> 88.148148 | K7: =IFERROR(COUNTIFS(ASISTENCIAS!$A:$A, $A7, ASISTENCIAS!$Y:$Y, TRUE) / COUNTIF(ASISTENCIAS!$A:$A, $A7)*100,0) -> 88.888889
A8: TEL_1 | B8: =B7+1 -> 7 | C8: MONTAJE Y MANEJO DE TELESCOPIOS | D8: TELESCOPIOS | E8: ASTRO | F8: 2025 | G8: MAR | H8: 3 | I8: =COUNTIF(ASISTENCIAS!$A:$A, $A8) -> 14 | J8: =IFERROR(SUMIF(ASISTENCIAS!$A:$A, $A8, ASISTENCIAS!$X:$X) / (COUNTIF(ASISTENCIAS!$A:$A, $A8) * $H8) * 100, 0) -> 71.428571 | K8: =IFERROR(COUNTIFS(ASISTENCIAS!$A:$A, $A8, ASISTENCIAS!$Y:$Y, TRUE) / COUNTIF(ASISTENCIAS!$A:$A, $A8)*100,0) -> 78.571429
A9: EST_1 | B9: =B8+1 -> 8 | C9: BIOGRAFÍA DE UNA ESTRELLA | D9: ESTRELLAS | E9: ASTRO | F9: 2025 | G9: MAY | H9: 5 | I9: =COUNTIF(ASISTENCIAS!$A:$A, $A9) -> 13 | J9: =IFERROR(SUMIF(ASISTENCIAS!$A:$A, $A9, ASISTENCIAS!$X:$X) / (COUNTIF(ASISTENCIAS!$A:$A, $A9) * $H9) * 100, 0) -> 64.615385 | K9: =IFERROR(COUNTIFS(ASISTENCIAS!$A:$A, $A9, ASISTENCIAS!$Y:$Y, TRUE) / COUNTIF(ASISTENCIAS!$A:$A, $A9)*100,0) -> 69.230769
A10: AJE_1 | B10: =B9+1 -> 9 | C10: AJEDREZ MATEMÁTICO | D10: MATEMÁTICAS EN EL AJEDREZ | E10: MATE | F10: 2025 | G10: MAY | H10: 8 | I10: =COUNTIF(ASISTENCIAS!$A:$A, $A10) -> 22 | J10: =IFERROR(SUMIF(ASISTENCIAS!$A:$A, $A10, ASISTENCIAS!$X:$X) / (COUNTIF(ASISTENCIAS!$A:$A, $A10) * $H10) * 100, 0) -> 65.340909 | K10: =IFERROR(COUNTIFS(ASISTENCIAS!$A:$A, $A10, ASISTENCIAS!$Y:$Y, TRUE) / COUNTIF(ASISTENCIAS!$A:$A, $A10)*100,0) -> 54.545455
A11: GAL_1 | B11: =B10+1 -> 10 | C11: EN UNA GALAXIA MUY, MUY LEJANA | D11: GALAXIAS | E11: ASTRO | F11: 2025 | G11: JUN | H11: 5 | I11: =COUNTIF(ASISTENCIAS!$A:$A, $A11) -> 13 | J11: =IFERROR(SUMIF(ASISTENCIAS!$A:$A, $A11, ASISTENCIAS!$X:$X) / (COUNTIF(ASISTENCIAS!$A:$A, $A11) * $H11) * 100, 0) -> 89.230769 | K11: =IFERROR(COUNTIFS(ASISTENCIAS!$A:$A, $A11, ASISTENCIAS!$Y:$Y, TRUE) / COUNTIF(ASISTENCIAS!$A:$A, $A11)*100,0) -> 92.307692
A12: EXO_1 | B12: =B11+1 -> 11 | C12: LARGA VIDA Y... EXOPLANETAS | D12: EXOPLANETAS | E12: ASTRO | F12: 2025 | G12: AGO | H12: 5 | I12: =COUNTIF(ASISTENCIAS!$A:$A, $A12) -> 18 | J12: =IFERROR(SUMIF(ASISTENCIAS!$A:$A, $A12, ASISTENCIAS!$X:$X) / (COUNTIF(ASISTENCIAS!$A:$A, $A12) * $H12) * 100, 0) -> 62.222222 | K12: =IFERROR(COUNTIFS(ASISTENCIAS!$A:$A, $A12, ASISTENCIAS!$Y:$Y, TRUE) / COUNTIF(ASISTENCIAS!$A:$A, $A12)*100,0) -> 61.111111
A13: EXP_1 | B13: =B12+1 -> 12 | C13: HOMO COSMICUS | D13: EXPLORACION | E13: ASTRO | F13: 2025 | G13: SEP | H13: 5 | I13: =COUNTIF(ASISTENCIAS!$A:$A, $A13) -> 12 | J13: =IFERROR(SUMIF(ASISTENCIAS!$A:$A, $A13, ASISTENCIAS!$X:$X) / (COUNTIF(ASISTENCIAS!$A:$A, $A13) * $H13) * 100, 0) -> 81.666667 | K13: =IFERROR(COUNTIFS(ASISTENCIAS!$A:$A, $A13, ASISTENCIAS!$Y:$Y, TRUE) / COUNTIF(ASISTENCIAS!$A:$A, $A13)*100,0) -> 75
A14: PRE_1 | B14: =B13+1 -> 13 | C14: MATEMÁTICAS PREOLÍMPICAS | D14: INTRODUCCION A LAS OLIMPIADAS DE MATEMÁTICAS | E14: MATE | F14: 2025 | G14: SEP | H14: 8 | I14: =COUNTIF(ASISTENCIAS!$A:$A, $A14) -> 8 | J14: =IFERROR(SUMIF(ASISTENCIAS!$A:$A, $A14, ASISTENCIAS!$X:$X) / (COUNTIF(ASISTENCIAS!$A:$A, $A14) * $H14) * 100, 0) -> 68.75 | K14: =IFERROR(COUNTIFS(ASISTENCIAS!$A:$A, $A14, ASISTENCIAS!$Y:$Y, TRUE) / COUNTIF(ASISTENCIAS!$A:$A, $A14)*100,0) -> 75
A15: CL_1 | B15: 14 | C15: GUARDIANES DE LA NOCHE | D15: CONTAMINACION LUMINICA | E15: ASTRO | F15: 2025 | G15: OCT | H15: 10 | I15: =COUNTIF(ASISTENCIAS!$A:$A, $A15) -> 84 | J15: =IFERROR(SUMIF(ASISTENCIAS!$A:$A, $A15, ASISTENCIAS!$X:$X) / (COUNTIF(ASISTENCIAS!$A:$A, $A15) * $H15) * 100, 0) -> 41.904762 | K15: =IFERROR(COUNTIFS(ASISTENCIAS!$A:$A, $A15, ASISTENCIAS!$Y:$Y, TRUE) / COUNTIF(ASISTENCIAS!$A:$A, $A15)*100,0) -> 57.142857
A16: COS_1 | B16: 15 | C16: EL DESPERTAR DEL COSMOS | D16: COSMOLOGIA | E16: ASTRO | F16: 2025 | G16: NOV | H16: 5 | I16: =COUNTIF(ASISTENCIAS!$A:$A, $A16) -> 16 | J16: =IFERROR(SUMIF(ASISTENCIAS!$A:$A, $A16, ASISTENCIAS!$X:$X) / (COUNTIF(ASISTENCIAS!$A:$A, $A16) * $H16) * 100, 0) -> 96.25 | K16: =IFERROR(COUNTIFS(ASISTENCIAS!$A:$A, $A16, ASISTENCIAS!$Y:$Y, TRUE) / COUNTIF(ASISTENCIAS!$A:$A, $A16)*100,0) -> 81.25
A17: COM_1 | B17: 16 | C17: COMBINATORIA | D17: COMBINATORIA | E17: MATE | F17: 2025 | G17: NOV | H17: 8 | I17: =COUNTIF(ASISTENCIAS!$A:$A, $A17) -> 9 | J17: =IFERROR(SUMIF(ASISTENCIAS!$A:$A, $A17, ASISTENCIAS!$X:$X) / (COUNTIF(ASISTENCIAS!$A:$A, $A17) * $H17) * 100, 0) -> 97.222222 | K17: =IFERROR(COUNTIFS(ASISTENCIAS!$A:$A, $A17, ASISTENCIAS!$Y:$Y, TRUE) / COUNTIF(ASISTENCIAS!$A:$A, $A17)*100,0) -> 100
A18: TEL_2 | B18: 17 | C18: MONTAJE Y MANEJO DE TELESCOPIOS | D18: TELESCOPIOS | E18: ASTRO | F18: 2025 | G18: DIC | H18: 5 | I18: =COUNTIF(ASISTENCIAS!$A:$A, $A18) -> 15 | J18: =IFERROR(SUMIF(ASISTENCIAS!$A:$A, $A18, ASISTENCIAS!$X:$X) / (COUNTIF(ASISTENCIAS!$A:$A, $A18) * $H18) * 100, 0) -> 73.333333 | K18: =IFERROR(COUNTIFS(ASISTENCIAS!$A:$A, $A18, ASISTENCIAS!$Y:$Y, TRUE) / COUNTIF(ASISTENCIAS!$A:$A, $A18)*100,0) -> 73.333333
A19: CON_2 | B19: 18 | C19: EL ROMPECABEZAS DEL CIELO | D19: CONSTELACIONES | E19: ASTRO | F19: 2026 | G19: ENE | H19: 5 | I19: =COUNTIF(ASISTENCIAS!$A:$A, $A19) -> 37 | J19: =IFERROR(SUMIF(ASISTENCIAS!$A:$A, $A19, ASISTENCIAS!$X:$X) / (COUNTIF(ASISTENCIAS!$A:$A, $A19) * $H19) * 100, 0) -> 10.810811 | K19: =IFERROR(COUNTIFS(ASISTENCIAS!$A:$A, $A19, ASISTENCIAS!$Y:$Y, TRUE) / COUNTIF(ASISTENCIAS!$A:$A, $A19)*100,0) -> 0
A20: NUM_1 | B20: 19 | C20: TEORÍA DE NÚMEROS | D20: TEORÍA DE NÚMEROS | E20: MATE | F20: 2026 | G20: ENE | H20: 8 | I20: =COUNTIF(ASISTENCIAS!$A:$A, $A20) -> 7 | J20: =IFERROR(SUMIF(ASISTENCIAS!$A:$A, $A20, ASISTENCIAS!$X:$X) / (COUNTIF(ASISTENCIAS!$A:$A, $A20) * $H20) * 100, 0) -> 23.214286 | K20: =IFERROR(COUNTIFS(ASISTENCIAS!$A:$A, $A20, ASISTENCIAS!$Y:$Y, TRUE) / COUNTIF(ASISTENCIAS!$A:$A, $A20)*100,0) -> 0
A21: IPhyC2025 | B21: 20 | C21: COMPETENCIA INTERNACIONAL DE FÍSICA | D21: FÍSICA | E21: FIS | F21: 2026 | G21: ENE | H21: por determinar | I21: =COUNTIF(ASISTENCIAS!$A:$A, $A21) -> 8 | J21: por determinar | K21: por determinar

Sheet REGOLITOS
A1: ID_Persona | B1: Nombre | C1: Año de ingreso | D1: Fecha de nacimiento | E1: Edad | F1: Ocupación | G1: Procedencia | H1: Telefono | I1: Correo | J1: Tutor | K1: Grupo de edad
A2: P0001 | B2: ="NombreDePersona_"&TEXT(ROW(A1),"000") -> NombreDePersona_001 | C2: 2025 | D2: =TODAY() - RANDBETWEEN(8*365, 99*365) -> 25545 | E2: =DATEDIF(D2, TODAY(), "Y") -> 56 | F2: Estudiante | G2: Estado de México | H2: ="55 55 "&TEXT(ROW(A1)-1,"0000")&" "&TEXT(ROW(A1)-1,"0000") -> 55 55 0000 0000 | I2: ="usuario"&ROW(A1)-1&"@ejemplo.com" -> usuario0@ejemplo.com | J2: =IF( DATEDIF(D2, DATE(2025,1,1), "Y") < 18, "Tutor_" & TEXT(ROW(A1)-1,"000"), "" ) | K2: =IF( E2="", "", IF( ISNUMBER(E2), IF(E2<=12,"Infancia", IF(E2<=17,"Adolescente", IF(E2<=29,"Jóven adulto", IF(E2<=59,"Adulto", IF(E2>=60,"Adulto Mayor","Desconocido") ) ) ) ), "Desconocido" )) -> Adulto
A3: P0002 | B3: ="NombreDePersona_"&TEXT(ROW(A2),"000") -> NombreDePersona_002 | C3: 2025 | D3: =TODAY() - RANDBETWEEN(8*365, 99*365) -> 42369 | E3: =DATEDIF(D3, TODAY(), "Y") -> 10 | F3: Docente | G3: Estado de México | H3: ="55 55 "&TEXT(ROW(A2)-1,"0000")&" "&TEXT(ROW(A2)-1,"0000") -> 55 55 0001 0001 | I3: ="usuario"&ROW(A2)-1&"@ejemplo.com" -> usuario1@ejemplo.com | J3: =IF( DATEDIF(D3, DATE(2025,1,1), "Y") < 18, "Tutor_" & TEXT(ROW(A2)-1,"000"), "" ) -> Tutor_001 | K3: =IF( E3="", "", IF( ISNUMBER(E3), IF(E3<=12,"Infancia", IF(E3<=17,"Adolescente", IF(E3<=29,"Jóven adulto", IF(E3<=59,"Adulto", IF(E3>=60,"Adulto Mayor","Desconocido") ) ) ) ), "Desconocido" )) -> Infancia
A4: P0003 | B4: ="NombreDePersona_"&TEXT(ROW(A3),"000") -> NombreDePersona_003 | C4: 2025 | D4: =TODAY() - RANDBETWEEN(8*365, 99*365) -> 13147 | E4: =DATEDIF(D4, TODAY(), "Y") -> 90 | F4: Docente | G4: Ciudad de México | H4: ="55 55 "&TEXT(ROW(A3)-1,"0000")&" "&TEXT(ROW(A3)-1,"0000") -> 55 55 0002 0002 | I4: ="usuario"&ROW(A3)-1&"@ejemplo.com" -> usuario2@ejemplo.com | J4: =IF( DATEDIF(D4, DATE(2025,1,1), "Y") < 18, "Tutor_" & TEXT(ROW(A3)-1,"000"), "" ) | K4: =IF( E4="", "", IF( ISNUMBER(E4), IF(E4<=12,"Infancia", IF(E4<=17,"Adolescente", IF(E4<=29,"Jóven adulto", IF(E4<=59,"Adulto", IF(E4>=60,"Adulto Mayor","Desconocido") ) ) ) ), "Desconocido" )) -> Adulto Mayor
A5: P0004 | B5: ="NombreDePersona_"&TEXT(ROW(A4),"000") -> NombreDePersona_004 | C5: 2025 | D5: =TODAY() - RANDBETWEEN(8*365, 99*365) -> 39872 | E5: =DATEDIF(D5, TODAY(), "Y") -> 16 | F5: Servidor público | G5: Ciudad de México | H5: ="55 55 "&TEXT(ROW(A4)-1,"0000")&" "&TEXT(ROW(A4)-1,"0000") -> 55 55 0003 0003 | I5: ="usuario"&ROW(A4)-1&"@ejemplo.com" -> usuario3@ejemplo.com | J5: =IF( DATEDIF(D5, DATE(2025,1,1), "Y") < 18, "Tutor_" & TEXT(ROW(A4)-1,"000"), "" ) -> Tutor_003 | K5: =IF( E5="", "", IF( ISNUMBER(E5), IF(E5<=12,"Infancia", IF(E5<=17,"Adolescente", IF(E5<=29,"Jóven adulto", IF(E5<=59,"Adulto", IF(E5>=60,"Adulto Mayor","Desconocido") ) ) ) ), "Desconocido" )) -> Adolescente
A6: P0005 | B6: ="NombreDePersona_"&TEXT(ROW(A5),"000") -> NombreDePersona_005 | C6: 2025 | D6: =TODAY() - RANDBETWEEN(8*365, 99*365) -> 38936 | E6: =DATEDIF(D6, TODAY(), "Y") -> 19 | F6: Perito criminalista | G6: Ciudad de México | H6: ="55 55 "&TEXT(ROW(A5)-1,"0000")&" "&TEXT(ROW(A5)-1,"0000") -> 55 55 0004 0004 | I6: ="usuario"&ROW(A5)-1&"@ejemplo.com" -> usuario4@ejemplo.com | J6: =IF( DATEDIF(D6, DATE(2025,1,1), "Y") < 18, "Tutor_" & TEXT(ROW(A5)-1,"000"), "" ) | K6: =IF( E6="", "", IF( ISNUMBER(E6), IF(E6<=12,"Infancia", IF(E6<=17,"Adolescente", IF(E6<=29,"Jóven adulto", IF(E6<=59,"Adulto", IF(E6>=60,"Adulto Mayor","Desconocido") ) ) ) ), "Desconocido" )) -> Jóven adulto
A7: P0006 | B7: ="NombreDePersona_"&TEXT(ROW(A6),"000") -> NombreDePersona_006 | C7: 2024 | D7: =TODAY() - RANDBETWEEN(8*365, 99*365) -> 27887 | E7: =DATEDIF(D7, TODAY(), "Y") -> 49 | F7: Desconocido | G7: Veracruz | H7: ="55 55 "&TEXT(ROW(A6)-1,"0000")&" "&TEXT(ROW(A6)-1,"0000") -> 55 55 0005 0005 | I7: ="usuario"&ROW(A6)-1&"@ejemplo.com" -> usuario5@ejemplo.com | J7: =IF( DATEDIF(D7, DATE(2025,1,1), "Y") < 18, "Tutor_" & TEXT(ROW(A6)-1,"000"), "" ) | K7: =IF( E7="", "", IF( ISNUMBER(E7), IF(E7<=12,"Infancia", IF(E7<=17,"Adolescente", IF(E7<=29,"Jóven adulto", IF(E7<=59,"Adulto", IF(E7>=60,"Adulto Mayor","Desconocido") ) ) ) ), "Desconocido" )) -> Adulto
A8: P0007 | B8: ="NombreDePersona_"&TEXT(ROW(A7),"000") -> NombreDePersona_007 | C8: 2025 | D8: =TODAY() - RANDBETWEEN(8*365, 99*365) -> 34115 | E8: =DATEDIF(D8, TODAY(), "Y") -> 32 | F8: Maestra | G8: Quintana Roo | H8: ="55 55 "&TEXT(ROW(A7)-1,"0000")&" "&TEXT(ROW(A7)-1,"0000") -> 55 55 0006 0006 | I8: ="usuario"&ROW(A7)-1&"@ejemplo.com" -> usuario6@ejemplo.com | J8: =IF( DATEDIF(D8, DATE(2025,1,1), "Y") < 18, "Tutor_" & TEXT(ROW(A7)-1,"000"), "" ) | K8: =IF( E8="", "", IF( ISNUMBER(E8), IF(E8<=12,"Infancia", IF(E8<=17,"Adolescente", IF(E8<=29,"Jóven adulto", IF(E8<=59,"Adulto", IF(E8>=60,"Adulto Mayor","Desconocido") ) ) ) ), "Desconocido" )) -> Adulto
A9: P0008 | B9: ="NombreDePersona_"&TEXT(ROW(A8),"000") -> NombreDePersona_008 | C9: 2025 | D9: =TODAY() - RANDBETWEEN(8*365, 99*365) -> 11303 | E9: =DATEDIF(D9, TODAY(), "Y") -> 95 | F9: Estudiante | G9: Ciudad de México | H9: ="55 55 "&TEXT(ROW(A8)-1,"0000")&" "&TEXT(ROW(A8)-1,"0000") -> 55 55 0007 0007 | I9: ="usuario"&ROW(A8)-1&"@ejemplo.com" -> usuario7@ejemplo.com | J9: =IF( DATEDIF(D9, DATE(2025,1,1), "Y") < 18, "Tutor_" & TEXT(ROW(A8)-1,"000"), "" ) | K9: =IF( E9="", "", IF( ISNUMBER(E9), IF(E9<=12,"Infancia", IF(E9<=17,"Adolescente", IF(E9<=29,"Jóven adulto", IF(E9<=59,"Adulto", IF(E9>=60,"Adulto Mayor","Desconocido") ) ) ) ), "Desconocido" )) -> Adulto Mayor
A10: P0009 | B10: ="NombreDePersona_"&TEXT(ROW(A9),"000") -> NombreDePersona_009 | C10: 2024 | D10: =TODAY() - RANDBETWEEN(8*365, 99*365) -> 18576 | E10: =DATEDIF(D10, TODAY(), "Y") -> 75 | F10: Investigadora | G10: Ciudad de México | H10: ="55 55 "&TEXT(ROW(A9)-1,"0000")&" "&TEXT(ROW(A9)-1,"0000") -> 55 55 0008 0008 | I10: ="usuario"&ROW(A9)-1&"@ejemplo.com" -> usuario8@ejemplo.com | J10: =IF( DATEDIF(D10, DATE(2025,1,1), "Y") < 18, "Tutor_" & TEXT(ROW(A9)-1,"000"), "" ) | K10: =IF( E10="", "", IF( ISNUMBER(E10), IF(E10<=12,"Infancia", IF(E10<=17,"Adolescente", IF(E10<=29,"Jóven adulto", IF(E10<=59,"Adulto", IF(E10>=60,"Adulto Mayor","Desconocido") ) ) ) ), "Desconocido" )) -> Adulto Mayor
A11: P0010 | B11: ="NombreDePersona_"&TEXT(ROW(A10),"000") -> NombreDePersona_010 | C11: 2025 | D11: =TODAY() - RANDBETWEEN(8*365, 99*365) -> 27024 | E11: =DATEDIF(D11, TODAY(), "Y") -> 52 | F11: Estudiante | G11: Estado de México | H11: ="55 55 "&TEXT(ROW(A10)-1,"0000")&" "&TEXT(ROW(A10)-1,"0000") -> 55 55 0009 0009 | I11: ="usuario"&ROW(A10)-1&"@ejemplo.com" -> usuario9@ejemplo.com | J11: =IF( DATEDIF(D11, DATE(2025,1,1), "Y") < 18, "Tutor_" & TEXT(ROW(A10)-1,"000"), "" ) | K11: =IF( E11="", "", IF( ISNUMBER(E11), IF(E11<=12,"Infancia", IF(E11<=17,"Adolescente", IF(E11<=29,"Jóven adulto", IF(E11<=59,"Adulto", IF(E11>=60,"Adulto Mayor","Desconocido") ) ) ) ), "Desconocido" )) -> Adulto
A12: P0011 | B12: ="NombreDePersona_"&TEXT(ROW(A11),"000") -> NombreDePersona_011 | C12: 2024 | D12: =TODAY() - RANDBETWEEN(8*365, 99*365) -> 17400 | E12: =DATEDIF(D12, TODAY(), "Y") -> 78 | F12: Estudiante | G12: Desconocido | H12: ="55 55 "&TEXT(ROW(A11)-1,"0000")&" "&TEXT(ROW(A11)-1,"0000") -> 55 55 0010 0010 | I12: ="usuario"&ROW(A11)-1&"@ejemplo.com" -> usuario10@ejemplo.com | J12: =IF( DATEDIF(D12, DATE(2025,1,1), "Y") < 18, "Tutor_" & TEXT(ROW(A11)-1,"000"), "" ) | K12: =IF( E12="", "", IF( ISNUMBER(E12), IF(E12<=12,"Infancia", IF(E12<=17,"Adolescente", IF(E12<=29,"Jóven adulto", IF(E12<=59,"Adulto", IF(E12>=60,"Adulto Mayor","Desconocido") ) ) ) ), "Desconocido" )) -> Adulto Mayor
A13: P0012 | B13: ="NombreDePersona_"&TEXT(ROW(A12),"000") -> NombreDePersona_012 | C13: 2025 | D13: =TODAY() - RANDBETWEEN(8*365, 99*365) -> 21417 | E13: =DATEDIF(D13, TODAY(), "Y") -> 67 | F13: Estudiante | G13: Chile | H13: ="55 55 "&TEXT(ROW(A12)-1,"0000")&" "&TEXT(ROW(A12)-1,"0000") -> 55 55 0011 0011 | I13: ="usuario"&ROW(A12)-1&"@ejemplo.com" -> usuario11@ejemplo.com | J13: =IF( DATEDIF(D13, DATE(2025,1,1), "Y") < 18, "Tutor_" & TEXT(ROW(A12)-1,"000"), "" ) | K13: =IF( E13="", "", IF( ISNUMBER(E13), IF(E13<=12,"Infancia", IF(E13<=17,"Adolescente", IF(E13<=29,"Jóven adulto", IF(E13<=59,"Adulto", IF(E13>=60,"Adulto Mayor","Desconocido") ) ) ) ), "Desconocido" )) -> Adulto Mayor
... A32: P0031 | B32: ="NombreDePersona_"&TEXT(ROW(A31),"000") -> NombreDePersona_031 | C32: 2024 | D32: =TODAY() - RANDBETWEEN(8*365, 99*365) -> 33049 | E32: =DATEDIF(D32, TODAY(), "Y") -> 35 | F32: Hogar | G32: Quintana Roo | H32: ="55 55 "&TEXT(ROW(A31)-1,"0000")&" "&TEXT(ROW(A31)-1,"0000") -> 55 55 0030 0030 | I32: ="usuario"&ROW(A31)-1&"@ejemplo.com" -> usuario30@ejemplo.com | J32: =IF( DATEDIF(D32, DATE(2025,1,1), "Y") < 18, "Tutor_" & TEXT(ROW(A31)-1,"000"), "" ) | K32: =IF( E32="", "", IF( ISNUMBER(E32), IF(E32<=12,"Infancia", IF(E32<=17,"Adolescente", IF(E32<=29,"Jóven adulto", IF(E32<=59,"Adulto", IF(E32>=60,"Adulto Mayor","Desconocido") ) ) ) ), "Desconocido" )) -> Adulto
A33: P0032 | B33: ="NombreDePersona_"&TEXT(ROW(A32),"000") -> NombreDePersona_032 | C33: 2024 | D33: =TODAY() - RANDBETWEEN(8*365, 99*365) -> 27600 | E33: =DATEDIF(D33, TODAY(), "Y") -> 50 | F33: Estudiante | G33: Desconocido | H33: ="55 55 "&TEXT(ROW(A32)-1,"0000")&" "&TEXT(ROW(A32)-1,"0000") -> 55 55 0031 0031 | I33: ="usuario"&ROW(A32)-1&"@ejemplo.com" -> usuario31@ejemplo.com | J33: =IF( DATEDIF(D33, DATE(2025,1,1), "Y") < 18, "Tutor_" & TEXT(ROW(A32)-1,"000"), "" ) | K33: Infancia
A34: P0033 | B34: ="NombreDePersona_"&TEXT(ROW(A33),"000") -> NombreDePersona_033 | C34: 2025 | D34: =TODAY() - RANDBETWEEN(8*365, 99*365) -> 34511 | E34: =DATEDIF(D34, TODAY(), "Y") -> 31 | F34: Estudiante | G34: Ciudad de México | H34: ="55 55 "&TEXT(ROW(A33)-1,"0000")&" "&TEXT(ROW(A33)-1,"0000") -> 55 55 0032 0032 | I34: ="usuario"&ROW(A33)-1&"@ejemplo.com" -> usuario32@ejemplo.com | J34: =IF( DATEDIF(D34, DATE(2025,1,1), "Y") < 18, "Tutor_" & TEXT(ROW(A33)-1,"000"), "" ) | K34: =IF( E34="", "", IF( ISNUMBER(E34), IF(E34<=12,"Infancia", IF(E34<=17,"Adolescente", IF(E34<=29,"Jóven adulto", IF(E34<=59,"Adulto", IF(E34>=60,"Adulto Mayor","Desconocido") ) ) ) ), "Desconocido" )) -> Adulto
A35: P0034 | B35: ="NombreDePersona_"&TEXT(ROW(A34),"000") -> NombreDePersona_034 | C35: 2024 | D35: =TODAY() - RANDBETWEEN(8*365, 99*365) -> 36378 | E35: =DATEDIF(D35, TODAY(), "Y") -> 26 | F35: Estudiante | G35: Desconocido | H35: ="55 55 "&TEXT(ROW(A34)-1,"0000")&" "&TEXT(ROW(A34)-1,"0000") -> 55 55 0033 0033 | I35: ="usuario"&ROW(A34)-1&"@ejemplo.com" -> usuario33@ejemplo.com | J35: =IF( DATEDIF(D35, DATE(2025,1,1), "Y") < 18, "Tutor_" & TEXT(ROW(A34)-1,"000"), "" ) | K35: Infancia
A36: P0035 | B36: ="NombreDePersona_"&TEXT(ROW(A35),"000") -> NombreDePersona_035 | C36: 2024 | D36: =TODAY() - RANDBETWEEN(8*365, 99*365) -> 28215 | E36: =DATEDIF(D36, TODAY(), "Y") -> 48 | F36: Desconocido | G36: Ciudad de México | H36: ="55 55 "&TEXT(ROW(A35)-1,"0000")&" "&TEXT(ROW(A35)-1,"0000") -> 55 55 0034 0034 | I36: ="usuario"&ROW(A35)-1&"@ejemplo.com" -> usuario34@ejemplo.com | J36: =IF( DATEDIF(D36, DATE(2025,1,1), "Y") < 18, "Tutor_" & TEXT(ROW(A35)-1,"000"), "" ) | K36: =IF( E36="", "", IF( ISNUMBER(E36), IF(E36<=12,"Infancia", IF(E36<=17,"Adolescente", IF(E36<=29,"Jóven adulto", IF(E36<=59,"Adulto", IF(E36>=60,"Adulto Mayor","Desconocido") ) ) ) ), "Desconocido" )) -> Adulto
A37: P0036 | B37: ="NombreDePersona_"&TEXT(ROW(A36),"000") -> NombreDePersona_036 | C37: 2025 | D37: =TODAY() - RANDBETWEEN(8*365, 99*365) -> 37467 | E37: =DATEDIF(D37, TODAY(), "Y") -> 23 | F37: Estudiante | G37: Jalisco | H37: ="55 55 "&TEXT(ROW(A36)-1,"0000")&" "&TEXT(ROW(A36)-1,"0000") -> 55 55 0035 0035 | I37: ="usuario"&ROW(A36)-1&"@ejemplo.com" -> usuario35@ejemplo.com | J37: =IF( DATEDIF(D37, DATE(2025,1,1), "Y") < 18, "Tutor_" & TEXT(ROW(A36)-1,"000"), "" ) | K37: =IF( E37="", "", IF( ISNUMBER(E37), IF(E37<=12,"Infancia", IF(E37<=17,"Adolescente", IF(E37<=29,"Jóven adulto", IF(E37<=59,"Adulto", IF(E37>=60,"Adulto Mayor","Desconocido") ) ) ) ), "Desconocido" )) -> Jóven adulto
A38: P0037 | B38: ="NombreDePersona_"&TEXT(ROW(A37),"000") -> NombreDePersona_037 | C38: 2025 | D38: =TODAY() - RANDBETWEEN(8*365, 99*365) -> 10104 | E38: =DATEDIF(D38, TODAY(), "Y") -> 98 | F38: Estudiante | G38: Sinaloa | H38: ="55 55 "&TEXT(ROW(A37)-1,"0000")&" "&TEXT(ROW(A37)-1,"0000") -> 55 55 0036 0036 | I38: ="usuario"&ROW(A37)-1&"@ejemplo.com" -> usuario36@ejemplo.com | J38: =IF( DATEDIF(D38, DATE(2025,1,1), "Y") < 18, "Tutor_" & TEXT(ROW(A37)-1,"000"), "" ) | K38: =IF( E38="", "", IF( ISNUMBER(E38), IF(E38<=12,"Infancia", IF(E38<=17,"Adolescente", IF(E38<=29,"Jóven adulto", IF(E38<=59,"Adulto", IF(E38>=60,"Adulto Mayor","Desconocido") ) ) ) ), "Desconocido" )) -> Adulto Mayor
A39: P0038 | B39: ="NombreDePersona_"&TEXT(ROW(A38),"000") -> NombreDePersona_038 | C39: 2024 | D39: =TODAY() - RANDBETWEEN(8*365, 99*365) -> 12186 | E39: =DATEDIF(D39, TODAY(), "Y") -> 92 | F39: Estudiante | G39: Estado de México | H39: ="55 55 "&TEXT(ROW(A38)-1,"0000")&" "&TEXT(ROW(A38)-1,"0000") -> 55 55 0037 0037 | I39: ="usuario"&ROW(A38)-1&"@ejemplo.com" -> usuario37@ejemplo.com | J39: =IF( DATEDIF(D39, DATE(2025,1,1), "Y") < 18, "Tutor_" & TEXT(ROW(A38)-1,"000"), "" ) | K39: =IF( E39="", "", IF( ISNUMBER(E39), IF(E39<=12,"Infancia", IF(E39<=17,"Adolescente", IF(E39<=29,"Jóven adulto", IF(E39<=59,"Adulto", IF(E39>=60,"Adulto Mayor","Desconocido") ) ) ) ), "Desconocido" )) -> Adulto Mayor
A40: P0039 | B40: ="NombreDePersona_"&TEXT(ROW(A39),"000") -> NombreDePersona_039 | C40: 2025 | D40: =TODAY() - RANDBETWEEN(8*365, 99*365) -> 14521 | E40: =DATEDIF(D40, TODAY(), "Y") -> 86 | F40: Estudiante | G40: Guerrero | H40: ="55 55 "&TEXT(ROW(A39)-1,"0000")&" "&TEXT(ROW(A39)-1,"0000") -> 55 55 0038 0038 | I40: ="usuario"&ROW(A39)-1&"@ejemplo.com" -> usuario38@ejemplo.com | J40: =IF( DATEDIF(D40, DATE(2025,1,1), "Y") < 18, "Tutor_" & TEXT(ROW(A39)-1,"000"), "" ) | K40: =IF( E40="", "", IF( ISNUMBER(E40), IF(E40<=12,"Infancia", IF(E40<=17,"Adolescente", IF(E40<=29,"Jóven adulto", IF(E40<=59,"Adulto", IF(E40>=60,"Adulto Mayor","Desconocido") ) ) ) ), "Desconocido" )) -> Adulto Mayor
A41: P0040 | B41: ="NombreDePersona_"&TEXT(ROW(A40),"000") -> NombreDePersona_040 | C41: 2025 | D41: =TODAY() - RANDBETWEEN(8*365, 99*365) -> 41113 | E41: =DATEDIF(D41, TODAY(), "Y") -> 13 | F41: Ama de casa | G41: Estado de México. | H41: ="55 55 "&TEXT(ROW(A40)-1,"0000")&" "&TEXT(ROW(A40)-1,"0000") -> 55 55 0039 0039 | I41: ="usuario"&ROW(A40)-1&"@ejemplo.com" -> usuario39@ejemplo.com | J41: =IF( DATEDIF(D41, DATE(2025,1,1), "Y") < 18, "Tutor_" & TEXT(ROW(A40)-1,"000"), "" ) -> Tutor_039 | K41: =IF( E41="", "", IF( ISNUMBER(E41), IF(E41<=12,"Infancia", IF(E41<=17,"Adolescente", IF(E41<=29,"Jóven adulto", IF(E41<=59,"Adulto", IF(E41>=60,"Adulto Mayor","Desconocido") ) ) ) ), "Desconocido" )) -> Adolescente
A42: P0041 | B42: ="NombreDePersona_"&TEXT(ROW(A41),"000") -> NombreDePersona_041 | C42: 2025 | D42: =TODAY() - RANDBETWEEN(8*365, 99*365) -> 11198 | E42: =DATEDIF(D42, TODAY(), "Y") -> 95 | F42: Terapeuta alternativo | G42: San Luís Potosí | H42: ="55 55 "&TEXT(ROW(A41)-1,"0000")&" "&TEXT(ROW(A41)-1,"0000") -> 55 55 0040 0040 | I42: ="usuario"&ROW(A41)-1&"@ejemplo.com" -> usuario40@ejemplo.com | J42: =IF( DATEDIF(D42, DATE(2025,1,1), "Y") < 18, "Tutor_" & TEXT(ROW(A41)-1,"000"), "" ) | K42: =IF( E42="", "", IF( ISNUMBER(E42), IF(E42<=12,"Infancia", IF(E42<=17,"Adolescente", IF(E42<=29,"Jóven adulto", IF(E42<=59,"Adulto", IF(E42>=60,"Adulto Mayor","Desconocido") ) ) ) ), "Desconocido" )) -> Adulto Mayor
A43: P0042 | B43: ="NombreDePersona_"&TEXT(ROW(A42),"000") -> NombreDePersona_042 | C43: 2025 | D43: =TODAY() - RANDBETWEEN(8*365, 99*365) -> 12937 | E43: =DATEDIF(D43, TODAY(), "Y") -> 90 | F43: Estudiante | G43: Ciudad de México | H43: ="55 55 "&TEXT(ROW(A42)-1,"0000")&" "&TEXT(ROW(A42)-1,"0000") -> 55 55 0041 0041 | I43: ="usuario"&ROW(A42)-1&"@ejemplo.com" -> usuario41@ejemplo.com | J43: =IF( DATEDIF(D43, DATE(2025,1,1), "Y") < 18, "Tutor_" & TEXT(ROW(A42)-1,"000"), "" ) | K43: =IF( E43="", "", IF( ISNUMBER(E43), IF(E43<=12,"Infancia", IF(E43<=17,"Adolescente", IF(E43<=29,"Jóven adulto", IF(E43<=59,"Adulto", IF(E43>=60,"Adulto Mayor","Desconocido") ) ) ) ), "Desconocido" )) -> Adulto Mayor
A44: P0043 | B44: ="NombreDePersona_"&TEXT(ROW(A43),"000") -> NombreDePersona_043 | C44: 2025 | D44: =TODAY() - RANDBETWEEN(8*365, 99*365) -> 35458 | E44: =DATEDIF(D44, TODAY(), "Y") -> 28 | F44: Estudiante | G44: Morelos | H44: ="55 55 "&TEXT(ROW(A43)-1,"0000")&" "&TEXT(ROW(A43)-1,"0000") -> 55 55 0042 0042 | I44: ="usuario"&ROW(A43)-1&"@ejemplo.com" -> usuario42@ejemplo.com | J44: =IF( DATEDIF(D44, DATE(2025,1,1), "Y") < 18, "Tutor_" & TEXT(ROW(A43)-1,"000"), "" ) | K44: =IF( E44="", "", IF( ISNUMBER(E44), IF(E44<=12,"Infancia", IF(E44<=17,"Adolescente", IF(E44<=29,"Jóven adulto", IF(E44<=59,"Adulto", IF(E44>=60,"Adulto Mayor","Desconocido") ) ) ) ), "Desconocido" )) -> Jóven adulto
A45: P0044 | B45: ="NombreDePersona_"&TEXT(ROW(A44),"000") -> NombreDePersona_044 | C45: 2025 | D45: =TODAY() - RANDBETWEEN(8*365, 99*365) -> 26404 | E45: =DATEDIF(D45, TODAY(), "Y") -> 53 | F45: Empleado | G45: Estado de México | H45: ="55 55 "&TEXT(ROW(A44)-1,"0000")&" "&TEXT(ROW(A44)-1,"0000") -> 55 55 0043 0043 | I45: ="usuario"&ROW(A44)-1&"@ejemplo.com" -> usuario43@ejemplo.com | J45: =IF( DATEDIF(D45, DATE(2025,1,1), "Y") < 18, "Tutor_" & TEXT(ROW(A44)-1,"000"), "" ) | K45: =IF( E45="", "", IF( ISNUMBER(E45), IF(E45<=12,"Infancia", IF(E45<=17,"Adolescente", IF(E45<=29,"Jóven adulto", IF(E45<=59,"Adulto", IF(E45>=60,"Adulto Mayor","Desconocido") ) ) ) ), "Desconocido" )) -> Adulto
A46: P0045 | B46: ="NombreDePersona_"&TEXT(ROW(A45),"000") -> NombreDePersona_045 | C46: 2025 | D46: =TODAY() - RANDBETWEEN(8*365, 99*365) -> 27136 | E46: =DATEDIF(D46, TODAY(), "Y") -> 51 | F46: Odontóloga | G46: Estado de México | H46: ="55 55 "&TEXT(ROW(A45)-1,"0000")&" "&TEXT(ROW(A45)-1,"0000") -> 55 55 0044 0044 | I46: ="usuario"&ROW(A45)-1&"@ejemplo.com" -> usuario44@ejemplo.com | J46: =IF( DATEDIF(D46, DATE(2025,1,1), "Y") < 18, "Tutor_" & TEXT(ROW(A45)-1,"000"), "" ) | K46: =IF( E46="", "", IF( ISNUMBER(E46), IF(E46<=12,"Infancia", IF(E46<=17,"Adolescente", IF(E46<=29,"Jóven adulto", IF(E46<=59,"Adulto", IF(E46>=60,"Adulto Mayor","Desconocido") ) ) ) ), "Desconocido" )) -> Adulto
A47: P0046 | B47: ="NombreDePersona_"&TEXT(ROW(A46),"000") -> NombreDePersona_046 | C47: 2025 | D47: =TODAY() - RANDBETWEEN(8*365, 99*365) -> 20583 | E47: =DATEDIF(D47, TODAY(), "Y") -> 69 | F47: Estudiante | G47: Ciudad de México | H47: ="55 55 "&TEXT(ROW(A46)-1,"0000")&" "&TEXT(ROW(A46)-1,"0000") -> 55 55 0045 0045 | I47: ="usuario"&ROW(A46)-1&"@ejemplo.com" -> usuario45@ejemplo.com | J47: =IF( DATEDIF(D47, DATE(2025,1,1), "Y") < 18, "Tutor_" & TEXT(ROW(A46)-1,"000"), "" ) | K47: =IF( E47="", "", IF( ISNUMBER(E47), IF(E47<=12,"Infancia", IF(E47<=17,"Adolescente", IF(E47<=29,"Jóven adulto", IF(E47<=59,"Adulto", IF(E47>=60,"Adulto Mayor","Desconocido") ) ) ) ), "Desconocido" )) -> Adulto Mayor
... A56: P0055 | B56: ="NombreDePersona_"&TEXT(ROW(A55),"000") -> NombreDePersona_055 | C56: 2025 | D56: =TODAY() - RANDBETWEEN(8*365, 99*365) -> 35050 | E56: =DATEDIF(D56, TODAY(), "Y") -> 30 | F56: Desconocido | G56: Desconocido | H56: ="55 55 "&TEXT(ROW(A55)-1,"0000")&" "&TEXT(ROW(A55)-1,"0000") -> 55 55 0054 0054 | I56: ="usuario"&ROW(A55)-1&"@ejemplo.com" -> usuario54@ejemplo.com | J56: =IF( DATEDIF(D56, DATE(2025,1,1), "Y") < 18, "Tutor_" & TEXT(ROW(A55)-1,"000"), "" ) | K56: =IF( E56="", "", IF( ISNUMBER(E56), IF(E56<=12,"Infancia", IF(E56<=17,"Adolescente", IF(E56<=29,"Jóven adulto", IF(E56<=59,"Adulto", IF(E56>=60,"Adulto Mayor","Desconocido") ) ) ) ), "Desconocido" )) -> Adulto
A57: P0056 | B57: ="NombreDePersona_"&TEXT(ROW(A56),"000") -> NombreDePersona_056 | C57: 2024 | D57: =TODAY() - RANDBETWEEN(8*365, 99*365) -> 36263 | E57: =DATEDIF(D57, TODAY(), "Y") -> 26 | F57: Estudiante | G57: Oaxaca | H57: ="55 55 "&TEXT(ROW(A56)-1,"0000")&" "&TEXT(ROW(A56)-1,"0000") -> 55 55 0055 0055 | I57: ="usuario"&ROW(A56)-1&"@ejemplo.com" -> usuario55@ejemplo.com | J57: =IF( DATEDIF(D57, DATE(2025,1,1), "Y") < 18, "Tutor_" & TEXT(ROW(A56)-1,"000"), "" ) | K57: Infancia
A58: P0057 | B58: ="NombreDePersona_"&TEXT(ROW(A57),"000") -> NombreDePersona_057 | C58: 2025 | D58: =TODAY() - RANDBETWEEN(8*365, 99*365) -> 36172 | E58: =DATEDIF(D58, TODAY(), "Y") -> 27 | F58: Estudiante | G58: Ciudad de México | H58: ="55 55 "&TEXT(ROW(A57)-1,"0000")&" "&TEXT(ROW(A57)-1,"0000") -> 55 55 0056 0056 | I58: ="usuario"&ROW(A57)-1&"@ejemplo.com" -> usuario56@ejemplo.com | J58: =IF( DATEDIF(D58, DATE(2025,1,1), "Y") < 18, "Tutor_" & TEXT(ROW(A57)-1,"000"), "" ) | K58: Infancia
A59: P0058 | B59: ="NombreDePersona_"&TEXT(ROW(A58),"000") -> NombreDePersona_058 | C59: 2025 | D59: =TODAY() - RANDBETWEEN(8*365, 99*365) -> 35888 | E59: =DATEDIF(D59, TODAY(), "Y") -> 27 | F59: Postdoctorante | G59: Jalisco | H59: ="55 55 "&TEXT(ROW(A58)-1,"0000")&" "&TEXT(ROW(A58)-1,"0000") -> 55 55 0057 0057 | I59: ="usuario"&ROW(A58)-1&"@ejemplo.com" -> usuario57@ejemplo.com | J59: =IF( DATEDIF(D59, DATE(2025,1,1), "Y") < 18, "Tutor_" & TEXT(ROW(A58)-1,"000"), "" ) | K59: =IF( E59="", "", IF( ISNUMBER(E59), IF(E59<=12,"Infancia", IF(E59<=17,"Adolescente", IF(E59<=29,"Jóven adulto", IF(E59<=59,"Adulto", IF(E59>=60,"Adulto Mayor","Desconocido") ) ) ) ), "Desconocido" )) -> Jóven adulto
A60: P0059 | B60: ="NombreDePersona_"&TEXT(ROW(A59),"000") -> NombreDePersona_059 | C60: 2025 | D60: =TODAY() - RANDBETWEEN(8*365, 99*365) -> 43102 | E60: =DATEDIF(D60, TODAY(), "Y") -> 8 | F60: Aula de medios | G60: Baja California | H60: ="55 55 "&TEXT(ROW(A59)-1,"0000")&" "&TEXT(ROW(A59)-1,"0000") -> 55 55 0058 0058 | I60: ="usuario"&ROW(A59)-1&"@ejemplo.com" -> usuario58@ejemplo.com | J60: =IF( DATEDIF(D60, DATE(2025,1,1), "Y") < 18, "Tutor_" & TEXT(ROW(A59)-1,"000"), "" ) -> Tutor_058 | K60: =IF( E60="", "", IF( ISNUMBER(E60), IF(E60<=12,"Infancia", IF(E60<=17,"Adolescente", IF(E60<=29,"Jóven adulto", IF(E60<=59,"Adulto", IF(E60>=60,"Adulto Mayor","Desconocido") ) ) ) ), "Desconocido" )) -> Infancia
A61: P0060 | B61: ="NombreDePersona_"&TEXT(ROW(A60),"000") -> NombreDePersona_060 | C61: 2025 | D61: =TODAY() - RANDBETWEEN(8*365, 99*365) -> 25230 | E61: =DATEDIF(D61, TODAY(), "Y") -> 56 | F61: Estudiante | G61: Ciudad de México | H61: ="55 55 "&TEXT(ROW(A60)-1,"0000")&" "&TEXT(ROW(A60)-1,"0000") -> 55 55 0059 0059 | I61: ="usuario"&ROW(A60)-1&"@ejemplo.com" -> usuario59@ejemplo.com | J61: =IF( DATEDIF(D61, DATE(2025,1,1), "Y") < 18, "Tutor_" & TEXT(ROW(A60)-1,"000"), "" ) | K61: =IF( E61="", "", IF( ISNUMBER(E61), IF(E61<=12,"Infancia", IF(E61<=17,"Adolescente", IF(E61<=29,"Jóven adulto", IF(E61<=59,"Adulto", IF(E61>=60,"Adulto Mayor","Desconocido") ) ) ) ), "Desconocido" )) -> Adulto
A62: P0061 | B62: ="NombreDePersona_"&TEXT(ROW(A61),"000") -> NombreDePersona_061 | C62: 2025 | D62: =TODAY() - RANDBETWEEN(8*365, 99*365) -> 38771 | E62: =DATEDIF(D62, TODAY(), "Y") -> 19 | F62: Desconocido | G62: Desconocido | H62: ="55 55 "&TEXT(ROW(A61)-1,"0000")&" "&TEXT(ROW(A61)-1,"0000") -> 55 55 0060 0060 | I62: ="usuario"&ROW(A61)-1&"@ejemplo.com" -> usuario60@ejemplo.com | J62: =IF( DATEDIF(D62, DATE(2025,1,1), "Y") < 18, "Tutor_" & TEXT(ROW(A61)-1,"000"), "" ) | K62: =IF( E62="", "", IF( ISNUMBER(E62), IF(E62<=12,"Infancia", IF(E62<=17,"Adolescente", IF(E62<=29,"Jóven adulto", IF(E62<=59,"Adulto", IF(E62>=60,"Adulto Mayor","Desconocido") ) ) ) ), "Desconocido" )) -> Jóven adulto
A63: P0062 | B63: ="NombreDePersona_"&TEXT(ROW(A62),"000") -> NombreDePersona_062 | C63: 2025 | D63: =TODAY() - RANDBETWEEN(8*365, 99*365) -> 10354 | E63: =DATEDIF(D63, TODAY(), "Y") -> 97 | F63: Estudiante | G63: Ciudad de México | H63: ="55 55 "&TEXT(ROW(A62)-1,"0000")&" "&TEXT(ROW(A62)-1,"0000") -> 55 55 0061 0061 | I63: ="usuario"&ROW(A62)-1&"@ejemplo.com" -> usuario61@ejemplo.com | J63: =IF( DATEDIF(D63, DATE(2025,1,1), "Y") < 18, "Tutor_" & TEXT(ROW(A62)-1,"000"), "" ) | K63: =IF( E63="", "", IF( ISNUMBER(E63), IF(E63<=12,"Infancia", IF(E63<=17,"Adolescente", IF(E63<=29,"Jóven adulto", IF(E63<=59,"Adulto", IF(E63>=60,"Adulto Mayor","Desconocido") ) ) ) ), "Desconocido" )) -> Adulto Mayor
A64: P0063 | B64: ="NombreDePersona_"&TEXT(ROW(A63),"000") -> NombreDePersona_063 | C64: 2025 | D64: =TODAY() - RANDBETWEEN(8*365, 99*365) -> 33167 | E64: =DATEDIF(D64, TODAY(), "Y") -> 35 | F64: Estudiante de Biología Marina | G64: Baja California Sur | H64: ="55 55 "&TEXT(ROW(A63)-1,"0000")&" "&TEXT(ROW(A63)-1,"0000") -> 55 55 0062 0062 | I64: ="usuario"&ROW(A63)-1&"@ejemplo.com" -> usuario62@ejemplo.com | J64: =IF( DATEDIF(D64, DATE(2025,1,1), "Y") < 18, "Tutor_" & TEXT(ROW(A63)-1,"000"), "" ) | K64: =IF( E64="", "", IF( ISNUMBER(E64), IF(E64<=12,"Infancia", IF(E64<=17,"Adolescente", IF(E64<=29,"Jóven adulto", IF(E64<=59,"Adulto", IF(E64>=60,"Adulto Mayor","Desconocido") ) ) ) ), "Desconocido" )) -> Adulto
A65: P0064 | B65: ="NombreDePersona_"&TEXT(ROW(A64),"000") -> NombreDePersona_064 | C65: 2025 | D65: =TODAY() - RANDBETWEEN(8*365, 99*365) -> 17654 | E65: =DATEDIF(D65, TODAY(), "Y") -> 77 | F65: Estudiante | G65: Ciudad de México | H65: ="55 55 "&TEXT(ROW(A64)-1,"0000")&" "&TEXT(ROW(A64)-1,"0000") -> 55 55 0063 0063 | I65: ="usuario"&ROW(A64)-1&"@ejemplo.com" -> usuario63@ejemplo.com | J65: =IF( DATEDIF(D65, DATE(2025,1,1), "Y") < 18, "Tutor_" & TEXT(ROW(A64)-1,"000"), "" ) | K65: =IF( E65="", "", IF( ISNUMBER(E65), IF(E65<=12,"Infancia", IF(E65<=17,"Adolescente", IF(E65<=29,"Jóven adulto", IF(E65<=59,"Adulto", IF(E65>=60,"Adulto Mayor","Desconocido") ) ) ) ), "Desconocido" )) -> Adulto Mayor
A66: P0065 | B66: ="NombreDePersona_"&TEXT(ROW(A65),"000") -> NombreDePersona_065 | C66: 2025 | D66: =TODAY() - RANDBETWEEN(8*365, 99*365) -> 40677 | E66: =DATEDIF(D66, TODAY(), "Y") -> 14 | F66: Estudiante | G66: Ciudad de México | H66: ="55 55 "&TEXT(ROW(A65)-1,"0000")&" "&TEXT(ROW(A65)-1,"0000") -> 55 55 0064 0064 | I66: ="usuario"&ROW(A65)-1&"@ejemplo.com" -> usuario64@ejemplo.com | J66: =IF( DATEDIF(D66, DATE(2025,1,1), "Y") < 18, "Tutor_" & TEXT(ROW(A65)-1,"000"), "" ) -> Tutor_064 | K66: =IF( E66="", "", IF( ISNUMBER(E66), IF(E66<=12,"Infancia", IF(E66<=17,"Adolescente", IF(E66<=29,"Jóven adulto", IF(E66<=59,"Adulto", IF(E66>=60,"Adulto Mayor","Desconocido") ) ) ) ), "Desconocido" )) -> Adolescente
...

Sheet ASISTENCIAS
A1: ID_Curso | B1: {=XLOOKUP(A1, CURSOS!A:A, CURSOS!B:B)} -> # | C1: {=XLOOKUP(A1, CURSOS!A:A, CURSOS!C:C)} -> Nombre_Curso | D1: ID_Persona | E1: Edad | F1: Ocupación | G1: Procedencia | H1: Telefono | I1: Correo | J1: Tutor | K1: Grupo de edad | L1: Pago | M1: S1 | N1: S2 | O1: S3 | P1: S4 | Q1: S5 | R1: S6 | S1: S7 | T1: S8 | U1: S9 | V1: S10 | W1: S11 | X1: % | Y1: Reconocimiento
A2: TIE_1 | B2: {=XLOOKUP(A2, CURSOS!A:A, CURSOS!B:B)} -> 1 | C2: {=XLOOKUP(A2, CURSOS!A:A, CURSOS!C:C)} -> NUESTRO HOGAR EN EL UNIVERSO | D2: P0029 | E2: {=XLOOKUP($D2,REGOLITOS!$A:$A,REGOLITOS!E:E)} -> 15 | F2: {=XLOOKUP($D2,REGOLITOS!$A:$A,REGOLITOS!F:F)} -> Ingeniería Civil | G2: {=XLOOKUP($D2,REGOLITOS!$A:$A,REGOLITOS!G:G)} -> Ciudad de México | H2: {=XLOOKUP($D2,REGOLITOS!$A:$A,REGOLITOS!H:H)} -> 55 55 0028 0028 | I2: {=XLOOKUP($D2,REGOLITOS!$A:$A,REGOLITOS!I:I)} -> usuario28@ejemplo.com | J2: {=XLOOKUP($D2,REGOLITOS!$A:$A,REGOLITOS!J:J)} -> Tutor_028 | K2: {=XLOOKUP($D2,REGOLITOS!$A:$A,REGOLITOS!K:K)} -> Adolescente | N2: Asistió | X2: =(COUNTIF(M2:W2, "Asistió")+COUNTIF(M2:W2, "Asíncrono")) -> 1 | Y2: TRUE
A3: TIE_1 | B3: {=XLOOKUP(A3, CURSOS!A:A, CURSOS!B:B)} -> 1 | C3: {=XLOOKUP(A3, CURSOS!A:A, CURSOS!C:C)} -> NUESTRO HOGAR EN EL UNIVERSO | D3: P0083 | E3: {=XLOOKUP($D3,REGOLITOS!$A:$A,REGOLITOS!E:E)} -> 66 | F3: {=XLOOKUP($D3,REGOLITOS!$A:$A,REGOLITOS!F:F)} -> Operadora de CTP | G3: {=XLOOKUP($D3,REGOLITOS!$A:$A,REGOLITOS!G:G)} -> Ciudad de México | H3: {=XLOOKUP($D3,REGOLITOS!$A:$A,REGOLITOS!H:H)} -> 55 55 0082 0082 | I3: {=XLOOKUP($D3,REGOLITOS!$A:$A,REGOLITOS!I:I)} -> usuario82@ejemplo.com | J3: {=XLOOKUP($D3,REGOLITOS!$A:$A,REGOLITOS!J:J)} | K3: {=XLOOKUP($D3,REGOLITOS!$A:$A,REGOLITOS!K:K)} -> Adulto Mayor | N3: Asistió | P3: Asistió | X3: =(COUNTIF(M3:W3, "Asistió")+COUNTIF(M3:W3, "Asíncrono")) -> 2 | Y3: TRUE
A4: TIE_1 | B4: {=XLOOKUP(A4, CURSOS!A:A, CURSOS!B:B)} -> 1 | C4: {=XLOOKUP(A4, CURSOS!A:A, CURSOS!C:C)} -> NUESTRO HOGAR EN EL UNIVERSO | D4: P0171 | E4: {=XLOOKUP($D4,REGOLITOS!$A:$A,REGOLITOS!E:E)} -> 45 | F4: {=XLOOKUP($D4,REGOLITOS!$A:$A,REGOLITOS!F:F)} -> Estudiante | G4: {=XLOOKUP($D4,REGOLITOS!$A:$A,REGOLITOS!G:G)} -> Estado de México | H4: {=XLOOKUP($D4,REGOLITOS!$A:$A,REGOLITOS!H:H)} -> 55 55 0170 0170 | I4: {=XLOOKUP($D4,REGOLITOS!$A:$A,REGOLITOS!I:I)} -> usuario170@ejemplo.com | J4: {=XLOOKUP($D4,REGOLITOS!$A:$A,REGOLITOS!J:J)} | K4: {=XLOOKUP($D4,REGOLITOS!$A:$A,REGOLITOS!K:K)} -> Adulto | N4: Asistió | P4: Asistió | X4: =(COUNTIF(M4:W4, "Asistió")+COUNTIF(M4:W4, "Asíncrono")) -> 2 | Y4: TRUE
A5: TIE_1 | B5: {=XLOOKUP(A5, CURSOS!A:A, CURSOS!B:B)} -> 1 | C5: {=XLOOKUP(A5, CURSOS!A:A, CURSOS!C:C)} -> NUESTRO HOGAR EN EL UNIVERSO | D5: P0016 | E5: {=XLOOKUP($D5,REGOLITOS!$A:$A,REGOLITOS!E:E)} -> 73 | F5: {=XLOOKUP($D5,REGOLITOS!$A:$A,REGOLITOS!F:F)} -> Docente | G5: {=XLOOKUP($D5,REGOLITOS!$A:$A,REGOLITOS!G:G)} -> Estado de México | H5: {=XLOOKUP($D5,REGOLITOS!$A:$A,REGOLITOS!H:H)} -> 55 55 0015 0015 | I5: {=XLOOKUP($D5,REGOLITOS!$A:$A,REGOLITOS!I:I)} -> usuario15@ejemplo.com | J5: {=XLOOKUP($D5,REGOLITOS!$A:$A,REGOLITOS!J:J)} | K5: {=XLOOKUP($D5,REGOLITOS!$A:$A,REGOLITOS!K:K)} -> Adulto Mayor | X5: =(COUNTIF(M5:W5, "Asistió")+COUNTIF(M5:W5, "Asíncrono")) -> 0 | Y5: TRUE
A6: TIE_1 | B6: {=XLOOKUP(A6, CURSOS!A:A, CURSOS!B:B)} -> 1 | C6: {=XLOOKUP(A6, CURSOS!A:A, CURSOS!C:C)} -> NUESTRO HOGAR EN EL UNIVERSO | D6: P0170 | E6: {=XLOOKUP($D6,REGOLITOS!$A:$A,REGOLITOS!E:E)} -> 53 | F6: {=XLOOKUP($D6,REGOLITOS!$A:$A,REGOLITOS!F:F)} -> Estudiante | G6: {=XLOOKUP($D6,REGOLITOS!$A:$A,REGOLITOS!G:G)} -> Ciudad de México | H6: {=XLOOKUP($D6,REGOLITOS!$A:$A,REGOLITOS!H:H)} -> 55 55 0169 0169 | I6: {=XLOOKUP($D6,REGOLITOS!$A:$A,REGOLITOS!I:I)} -> usuario169@ejemplo.com | J6: {=XLOOKUP($D6,REGOLITOS!$A:$A,REGOLITOS!J:J)} | K6: {=XLOOKUP($D6,REGOLITOS!$A:$A,REGOLITOS!K:K)} -> Adulto | L6: G | N6: Asistió | P6: Asistió | X6: =(COUNTIF(M6:W6, "Asistió")+COUNTIF(M6:W6, "Asíncrono")) -> 2 | Y6: TRUE
A7: TIE_1 | B7: {=XLOOKUP(A7, CURSOS!A:A, CURSOS!B:B)} -> 1 | C7: {=XLOOKUP(A7, CURSOS!A:A, CURSOS!C:C)} -> NUESTRO HOGAR EN EL UNIVERSO | D7: P0045 | E7: {=XLOOKUP($D7,REGOLITOS!$A:$A,REGOLITOS!E:E)} -> 51 | F7: {=XLOOKUP($D7,REGOLITOS!$A:$A,REGOLITOS!F:F)} -> Odontóloga | G7: {=XLOOKUP($D7,REGOLITOS!$A:$A,REGOLITOS!G:G)} -> Estado de México | H7: {=XLOOKUP($D7,REGOLITOS!$A:$A,REGOLITOS!H:H)} -> 55 55 0044 0044 | I7: {=XLOOKUP($D7,REGOLITOS!$A:$A,REGOLITOS!I:I)} -> usuario44@ejemplo.com | J7: {=XLOOKUP($D7,REGOLITOS!$A:$A,REGOLITOS!J:J)} | K7: {=XLOOKUP($D7,REGOLITOS!$A:$A,REGOLITOS!K:K)} -> Adulto | N7: Asistió | P7: Asistió | X7: =(COUNTIF(M7:W7, "Asistió")+COUNTIF(M7:W7, "Asíncrono")) -> 2 | Y7: TRUE
A8: TIE_1 | B8: {=XLOOKUP(A8, CURSOS!A:A, CURSOS!B:B)} -> 1 | C8: {=XLOOKUP(A8, CURSOS!A:A, CURSOS!C:C)} -> NUESTRO HOGAR EN EL UNIVERSO | D8: P0188 | E8: {=XLOOKUP($D8,REGOLITOS!$A:$A,REGOLITOS!E:E)} -> 47 | F8: {=XLOOKUP($D8,REGOLITOS!$A:$A,REGOLITOS!F:F)} -> Jubilada | G8: {=XLOOKUP($D8,REGOLITOS!$A:$A,REGOLITOS!G:G)} -> Quintana Roo | H8: {=XLOOKUP($D8,REGOLITOS!$A:$A,REGOLITOS!H:H)} -> 55 55 0187 0187 | I8: {=XLOOKUP($D8,REGOLITOS!$A:$A,REGOLITOS!I:I)} -> usuario187@ejemplo.com | J8: {=XLOOKUP($D8,REGOLITOS!$A:$A,REGOLITOS!J:J)} | K8: {=XLOOKUP($D8,REGOLITOS!$A:$A,REGOLITOS!K:K)} -> Adulto | X8: =(COUNTIF(M8:W8, "Asistió")+COUNTIF(M8:W8, "Asíncrono")) -> 0 | Y8: TRUE
A9: LUN_1 | B9: {=XLOOKUP(A9, CURSOS!A:A, CURSOS!B:B)} -> 2 | C9: {=XLOOKUP(A9, CURSOS!A:A, CURSOS!C:C)} -> EN EL OMBLIGO DE LA LUNA | D9: P0083 | E9: {=XLOOKUP($D9,REGOLITOS!$A:$A,REGOLITOS!E:E)} -> 66 | F9: {=XLOOKUP($D9,REGOLITOS!$A:$A,REGOLITOS!F:F)} -> Operadora de CTP | G9: {=XLOOKUP($D9,REGOLITOS!$A:$A,REGOLITOS!G:G)} -> Ciudad de México | H9: {=XLOOKUP($D9,REGOLITOS!$A:$A,REGOLITOS!H:H)} -> 55 55 0082 0082 | I9: {=XLOOKUP($D9,REGOLITOS!$A:$A,REGOLITOS!I:I)} -> usuario82@ejemplo.com | J9: {=XLOOKUP($D9,REGOLITOS!$A:$A,REGOLITOS!J:J)} | K9: {=XLOOKUP($D9,REGOLITOS!$A:$A,REGOLITOS!K:K)} -> Adulto Mayor | L9: 160 | M9: Asistió | N9: Asistió | O9: Asistió | P9: Asistió | Q9: Asistió | X9: =(COUNTIF(M9:W9, "Asistió")+COUNTIF(M9:W9, "Asíncrono")) -> 5 | Y9: TRUE
A10: LUN_1 | B10: {=XLOOKUP(A10, CURSOS!A:A, CURSOS!B:B)} -> 2 | C10: {=XLOOKUP(A10, CURSOS!A:A, CURSOS!C:C)} -> EN EL OMBLIGO DE LA LUNA | D10: P0171 | E10: {=XLOOKUP($D10,REGOLITOS!$A:$A,REGOLITOS!E:E)} -> 45 | F10: {=XLOOKUP($D10,REGOLITOS!$A:$A,REGOLITOS!F:F)} -> Estudiante | G10: {=XLOOKUP($D10,REGOLITOS!$A:$A,REGOLITOS!G:G)} -> Estado de México | H10: {=XLOOKUP($D10,REGOLITOS!$A:$A,REGOLITOS!H:H)} -> 55 55 0170 0170 | I10: {=XLOOKUP($D10,REGOLITOS!$A:$A,REGOLITOS!I:I)} -> usuario170@ejemplo.com | J10: {=XLOOKUP($D10,REGOLITOS!$A:$A,REGOLITOS!J:J)} | K10: {=XLOOKUP($D10,REGOLITOS!$A:$A,REGOLITOS!K:K)} -> Adulto | L10: 160 | M10: Asistió | N10: Asistió | O10: Asistió | P10: Asistió | Q10: Asistió | X10: =(COUNTIF(M10:W10, "Asistió")+COUNTIF(M10:W10, "Asíncrono")) -> 5 | Y10: TRUE
A11: LUN_1 | B11: {=XLOOKUP(A11, CURSOS!A:A, CURSOS!B:B)} -> 2 | C11: {=XLOOKUP(A11, CURSOS!A:A, CURSOS!C:C)} -> EN EL OMBLIGO DE LA LUNA | D11: P0073 | E11: {=XLOOKUP($D11,REGOLITOS!$A:$A,REGOLITOS!E:E)} -> 73 | F11: {=XLOOKUP($D11,REGOLITOS!$A:$A,REGOLITOS!F:F)} -> Estudiante | G11: {=XLOOKUP($D11,REGOLITOS!$A:$A,REGOLITOS!G:G)} -> Nuevo León | H11: {=XLOOKUP($D11,REGOLITOS!$A:$A,REGOLITOS!H:H)} -> 55 55 0072 0072 | I11: {=XLOOKUP($D11,REGOLITOS!$A:$A,REGOLITOS!I:I)} -> usuario72@ejemplo.com | J11: {=XLOOKUP($D11,REGOLITOS!$A:$A,REGOLITOS!J:J)} | K11: {=XLOOKUP($D11,REGOLITOS!$A:$A,REGOLITOS!K:K)} -> Infancia | L11: 200 | M11: Asistió | N11: Asistió | O11: Asistió | P11: Asistió | Q11: Asistió | X11: =(COUNTIF(M11:W11, "Asistió")+COUNTIF(M11:W11, "Asíncrono")) -> 5 | Y11: TRUE
A12: LUN_1 | B12: {=XLOOKUP(A12, CURSOS!A:A, CURSOS!B:B)} -> 2 | C12: {=XLOOKUP(A12, CURSOS!A:A, CURSOS!C:C)} -> EN EL OMBLIGO DE LA LUNA | D12: P0029 | E12: {=XLOOKUP($D12,REGOLITOS!$A:$A,REGOLITOS!E:E)} -> 15 | F12: {=XLOOKUP($D12,REGOLITOS!$A:$A,REGOLITOS!F:F)} -> Ingeniería Civil | G12: {=XLOOKUP($D12,REGOLITOS!$A:$A,REGOLITOS!G:G)} -> Ciudad de México | H12: {=XLOOKUP($D12,REGOLITOS!$A:$A,REGOLITOS!H:H)} -> 55 55 0028 0028 | I12: {=XLOOKUP($D12,REGOLITOS!$A:$A,REGOLITOS!I:I)} -> usuario28@ejemplo.com | J12: {=XLOOKUP($D12,REGOLITOS!$A:$A,REGOLITOS!J:J)} -> Tutor_028 | K12: {=XLOOKUP($D12,REGOLITOS!$A:$A,REGOLITOS!K:K)} -> Adolescente | L12: 160 | M12: Asistió | N12: Asistió | O12: Asistió | P12: Asistió | Q12: Asistió | X12: =(COUNTIF(M12:W12, "Asistió")+COUNTIF(M12:W12, "Asíncrono")) -> 5 | Y12: TRUE
A13: LUN_1 | B13: {=XLOOKUP(A13, CURSOS!A:A, CURSOS!B:B)} -> 2 | C13: {=XLOOKUP(A13, CURSOS!A:A, CURSOS!C:C)} -> EN EL OMBLIGO DE LA LUNA | D13: P0104 | E13: {=XLOOKUP($D13,REGOLITOS!$A:$A,REGOLITOS!E:E)} -> 66 | F13: {=XLOOKUP($D13,REGOLITOS!$A:$A,REGOLITOS!F:F)} -> Estudiante HS | G13: {=XLOOKUP($D13,REGOLITOS!$A:$A,REGOLITOS!G:G)} -> Jalisco | H13: {=XLOOKUP($D13,REGOLITOS!$A:$A,REGOLITOS!H:H)} -> 55 55 0103 0103 | I13: {=XLOOKUP($D13,REGOLITOS!$A:$A,REGOLITOS!I:I)} -> usuario103@ejemplo.com | J13: {=XLOOKUP($D13,REGOLITOS!$A:$A,REGOLITOS!J:J)} | K13: {=XLOOKUP($D13,REGOLITOS!$A:$A,REGOLITOS!K:K)} -> Adulto Mayor | L13: 200 | M13: Asistió | N13: Asistió | O13: Asistió | P13: Asistió | Q13: Asistió | X13: =(COUNTIF(M13:W13, "Asistió")+COUNTIF(M13:W13, "Asíncrono")) -> 5 | Y13: TRUE
A14: LUN_1 | B14: {=XLOOKUP(A14, CURSOS!A:A, CURSOS!B:B)} -> 2 | C14: {=XLOOKUP(A14, CURSOS!A:A, CURSOS!C:C)} -> EN EL OMBLIGO DE LA LUNA | D14: P0086 | E14: {=XLOOKUP($D14,REGOLITOS!$A:$A,REGOLITOS!E:E)} -> 18 | F14: {=XLOOKUP($D14,REGOLITOS!$A:$A,REGOLITOS!F:F)} -> Estudiante | G14: {=XLOOKUP($D14,REGOLITOS!$A:$A,REGOLITOS!G:G)} -> Hidalgo | H14: {=XLOOKUP($D14,REGOLITOS!$A:$A,REGOLITOS!H:H)} -> 55 55 0085 0085 | I14: {=XLOOKUP($D14,REGOLITOS!$A:$A,REGOLITOS!I:I)} -> usuario85@ejemplo.com | J14: {=XLOOKUP($D14,REGOLITOS!$A:$A,REGOLITOS!J:J)} -> Tutor_085 | K14: {=XLOOKUP($D14,REGOLITOS!$A:$A,REGOLITOS!K:K)} -> Jóven adulto | L14: 200 | M14: Faltó | N14: Asistió | O14: Asistió | P14: Asistió | Q14: Asistió | X14: =(COUNTIF(M14:W14, "Asistió")+COUNTIF(M14:W14, "Asíncrono")) -> 4 | Y14: TRUE
A15: LUN_1 | B15: {=XLOOKUP(A15, CURSOS!A:A, CURSOS!B:B)} -> 2 | C15: {=XLOOKUP(A15, CURSOS!A:A, CURSOS!C:C)} -> EN EL OMBLIGO DE LA LUNA | D15: P0167 | E15: {=XLOOKUP($D15,REGOLITOS!$A:$A,REGOLITOS!E:E)} -> 47 | F15: {=XLOOKUP($D15,REGOLITOS!$A:$A,REGOLITOS!F:F)} -> Desconocido | G15: {=XLOOKUP($D15,REGOLITOS!$A:$A,REGOLITOS!G:G)} -> Estado de México | H15: {=XLOOKUP($D15,REGOLITOS!$A:$A,REGOLITOS!H:H)} -> 55 55 0166 0166 | I15: {=XLOOKUP($D15,REGOLITOS!$A:$A,REGOLITOS!I:I)} -> usuario166@ejemplo.com | J15: {=XLOOKUP($D15,REGOLITOS!$A:$A,REGOLITOS!J:J)} | K15: {=XLOOKUP($D15,REGOLITOS!$A:$A,REGOLITOS!K:K)} -> Adulto | L15: 200 | M15: Asistió | N15: Faltó | O15: Asistió | P15: Asistió | Q15: Asistió | X15: =(COUNTIF(M15:W15, "Asistió")+COUNTIF(M15:W15, "Asíncrono")) -> 4 | Y15: TRUE
A16: LUN_1 | B16: {=XLOOKUP(A16, CURSOS!A:A, CURSOS!B:B)} -> 2 | C16: {=XLOOKUP(A16, CURSOS!A:A, CURSOS!C:C)} -> EN EL OMBLIGO DE LA LUNA | D16: P0038 | E16: {=XLOOKUP($D16,REGOLITOS!$A:$A,REGOLITOS!E:E)} -> 92 | F16: {=XLOOKUP($D16,REGOLITOS!$A:$A,REGOLITOS!F:F)} -> Estudiante | G16: {=XLOOKUP($D16,REGOLITOS!$A:$A,REGOLITOS!G:G)} -> Estado de México | H16: {=XLOOKUP($D16,REGOLITOS!$A:$A,REGOLITOS!H:H)} -> 55 55 0037 0037 | I16: {=XLOOKUP($D16,REGOLITOS!$A:$A,REGOLITOS!I:I)} -> usuario37@ejemplo.com | J16: {=XLOOKUP($D16,REGOLITOS!$A:$A,REGOLITOS!J:J)} | K16: {=XLOOKUP($D16,REGOLITOS!$A:$A,REGOLITOS!K:K)} -> Adulto Mayor | L16: 200 | M16: Asistió | N16: Asistió | O16: Faltó | P16: Asistió | Q16: Asistió | X16: =(COUNTIF(M16:W16, "Asistió")+COUNTIF(M16:W16, "Asíncrono")) -> 4 | Y16: TRUE
A17: LUN_1 | B17: {=XLOOKUP(A17, CURSOS!A:A, CURSOS!B:B)} -> 2 | C17: {=XLOOKUP(A17, CURSOS!A:A, CURSOS!C:C)} -> EN EL OMBLIGO DE LA LUNA | D17: P0129 | E17: {=XLOOKUP($D17,REGOLITOS!$A:$A,REGOLITOS!E:E)} -> 46 | F17: {=XLOOKUP($D17,REGOLITOS!$A:$A,REGOLITOS!F:F)} -> Administración | G17: {=XLOOKUP($D17,REGOLITOS!$A:$A,REGOLITOS!G:G)} -> Ciudad de México | H17: {=XLOOKUP($D17,REGOLITOS!$A:$A,REGOLITOS!H:H)} -> 55 55 0128 0128 | I17: {=XLOOKUP($D17,REGOLITOS!$A:$A,REGOLITOS!I:I)} -> usuario128@ejemplo.com | J17: {=XLOOKUP($D17,REGOLITOS!$A:$A,REGOLITOS!J:J)} | K17: {=XLOOKUP($D17,REGOLITOS!$A:$A,REGOLITOS!K:K)} -> Adulto | L17: 200 | M17: Asistió | N17: Asistió | O17: Asistió | P17: Faltó | Q17: Asistió | X17: =(COUNTIF(M17:W17, "Asistió")+COUNTIF(M17:W17, "Asíncrono")) -> 4 | Y17: TRUE
A18: LUN_1 | B18: {=XLOOKUP(A18, CURSOS!A:A, CURSOS!B:B)} -> 2 | C18: {=XLOOKUP(A18, CURSOS!A:A, CURSOS!C:C)} -> EN EL OMBLIGO DE LA LUNA | D18: P0105 | E18: {=XLOOKUP($D18,REGOLITOS!$A:$A,REGOLITOS!E:E)} -> 24 | F18: {=XLOOKUP($D18,REGOLITOS!$A:$A,REGOLITOS!F:F)} -> Estudiante | G18: {=XLOOKUP($D18,REGOLITOS!$A:$A,REGOLITOS!G:G)} -> México | H18: {=XLOOKUP($D18,REGOLITOS!$A:$A,REGOLITOS!H:H)} -> 55 55 0104 0104 | I18: {=XLOOKUP($D18,REGOLITOS!$A:$A,REGOLITOS!I:I)} -> usuario104@ejemplo.com | J18: {=XLOOKUP($D18,REGOLITOS!$A:$A,REGOLITOS!J:J)} | K18: {=XLOOKUP($D18,REGOLITOS!$A:$A,REGOLITOS!K:K)} -> Infancia | L18: 200 | M18: Asistió | N18: Asistió | O18: Asistió | P18: Asistió | Q18: Faltó | X18: =(COUNTIF(M18:W18, "Asistió")+COUNTIF(M18:W18, "Asíncrono")) -> 4 | Y18: TRUE
A19: LUN_1 | B19: {=XLOOKUP(A19, CURSOS!A:A, CURSOS!B:B)} -> 2 | C19: {=XLOOKUP(A19, CURSOS!A:A, CURSOS!C:C)} -> EN EL OMBLIGO DE LA LUNA | D19: P0164 | E19: {=XLOOKUP($D19,REGOLITOS!$A:$A,REGOLITOS!E:E)} -> 61 | F19: {=XLOOKUP($D19,REGOLITOS!$A:$A,REGOLITOS!F:F)} -> Desconocido | G19: {=XLOOKUP($D19,REGOLITOS!$A:$A,REGOLITOS!G:G)} -> Jalisco | H19: {=XLOOKUP($D19,REGOLITOS!$A:$A,REGOLITOS!H:H)} -> 55 55 0163 0163 | I19: {=XLOOKUP($D19,REGOLITOS!$A:$A,REGOLITOS!I:I)} -> usuario163@ejemplo.com | J19: {=XLOOKUP($D19,REGOLITOS!$A:$A,REGOLITOS!J:J)} | K19: {=XLOOKUP($D19,REGOLITOS!$A:$A,REGOLITOS!K:K)} -> Adulto | L19: 200 | M19: Faltó | N19: Asistió | O19: Faltó | P19: Asistió | Q19: Asistió | X19: =(COUNTIF(M19:W19, "Asistió")+COUNTIF(M19:W19, "Asíncrono")) -> 3 | Y19: FALSE
A20: LUN_1 | B20: {=XLOOKUP(A20, CURSOS!A:A, CURSOS!B:B)} -> 2 | C20: {=XLOOKUP(A20, CURSOS!A:A, CURSOS!C:C)} -> EN EL OMBLIGO DE LA LUNA | D20: P0112 | E20: {=XLOOKUP($D20,REGOLITOS!$A:$A,REGOLITOS!E:E)} -> 25 | F20: {=XLOOKUP($D20,REGOLITOS!$A:$A,REGOLITOS!F:F)} -> Desconocido | G20: {=XLOOKUP($D20,REGOLITOS!$A:$A,REGOLITOS!G:G)} -> Estado de México | H20: {=XLOOKUP($D20,REGOLITOS!$A:$A,REGOLITOS!H:H)} -> 55 55 0111 0111 | I20: {=XLOOKUP($D20,REGOLITOS!$A:$A,REGOLITOS!I:I)} -> usuario111@ejemplo.com | J20: {=XLOOKUP($D20,REGOLITOS!$A:$A,REGOLITOS!J:J)} | K20: {=XLOOKUP($D20,REGOLITOS!$A:$A,REGOLITOS!K:K)} -> Adulto | L20: 200 | M20: Asistió | N20: Faltó | O20: Faltó | P20: Asistió | Q20: Asistió | X20: =(COUNTIF(M20:W20, "Asistió")+COUNTIF(M20:W20, "Asíncrono")) -> 3 | Y20: FALSE
... A33: SOL_1 | B33: {=XLOOKUP(A33, CURSOS!A:A, CURSOS!B:B)} -> 3 | C33: {=XLOOKUP(A33, CURSOS!A:A, CURSOS!C:C)} -> LA ESTRELLA QUE NOS ILUMINA | D33: P0034 | E33: {=XLOOKUP($D33,REGOLITOS!$A:$A,REGOLITOS!E:E)} -> 26 | F33: {=XLOOKUP($D33,REGOLITOS!$A:$A,REGOLITOS!F:F)} -> Estudiante | G33: {=XLOOKUP($D33,REGOLITOS!$A:$A,REGOLITOS!G:G)} -> Desconocido | H33: {=XLOOKUP($D33,REGOLITOS!$A:$A,REGOLITOS!H:H)} -> 55 55 0033 0033 | I33: {=XLOOKUP($D33,REGOLITOS!$A:$A,REGOLITOS!I:I)} -> usuario33@ejemplo.com | J33: {=XLOOKUP($D33,REGOLITOS!$A:$A,REGOLITOS!J:J)} | K33: {=XLOOKUP($D33,REGOLITOS!$A:$A,REGOLITOS!K:K)} -> Infancia | L33: 200 | M33: Faltó | N33: Faltó | O33: Faltó | P33: Faltó | Q33: Faltó | X33: =(COUNTIF(M33:W33, "Asistió")+COUNTIF(M33:W33, "Asíncrono")) -> 0 | Y33: FALSE
A34: SS_1 | B34: {=XLOOKUP(A34, CURSOS!A:A, CURSOS!B:B)} -> 4 | C34: {=XLOOKUP(A34, CURSOS!A:A, CURSOS!C:C)} -> VAGABUNDOS DEL FIRMAMENTO | D34: P0015 | E34: {=XLOOKUP($D34,REGOLITOS!$A:$A,REGOLITOS!E:E)} -> 81 | F34: {=XLOOKUP($D34,REGOLITOS!$A:$A,REGOLITOS!F:F)} -> Estudiante | G34: {=XLOOKUP($D34,REGOLITOS!$A:$A,REGOLITOS!G:G)} -> Sinaloa | H34: {=XLOOKUP($D34,REGOLITOS!$A:$A,REGOLITOS!H:H)} -> 55 55 0014 0014 | I34: {=XLOOKUP($D34,REGOLITOS!$A:$A,REGOLITOS!I:I)} -> usuario14@ejemplo.com | J34: {=XLOOKUP($D34,REGOLITOS!$A:$A,REGOLITOS!J:J)} | K34: {=XLOOKUP($D34,REGOLITOS!$A:$A,REGOLITOS!K:K)} -> Adulto Mayor | M34: Asistió | N34: Asistió | O34: Asistió | P34: Asistió | Q34: Asistió | X34: =(COUNTIF(M34:W34, "Asistió")+COUNTIF(M34:W34, "Asíncrono")) -> 5 | Y34: TRUE
A35: SS_1 | B35: {=XLOOKUP(A35, CURSOS!A:A, CURSOS!B:B)} -> 4 | C35: {=XLOOKUP(A35, CURSOS!A:A, CURSOS!C:C)} -> VAGABUNDOS DEL FIRMAMENTO | D35: P0171 | E35: {=XLOOKUP($D35,REGOLITOS!$A:$A,REGOLITOS!E:E)} -> 45 | F35: {=XLOOKUP($D35,REGOLITOS!$A:$A,REGOLITOS!F:F)} -> Estudiante | G35: {=XLOOKUP($D35,REGOLITOS!$A:$A,REGOLITOS!G:G)} -> Estado de México | H35: {=XLOOKUP($D35,REGOLITOS!$A:$A,REGOLITOS!H:H)} -> 55 55 0170 0170 | I35: {=XLOOKUP($D35,REGOLITOS!$A:$A,REGOLITOS!I:I)} -> usuario170@ejemplo.com | J35: {=XLOOKUP($D35,REGOLITOS!$A:$A,REGOLITOS!J:J)} | K35: {=XLOOKUP($D35,REGOLITOS!$A:$A,REGOLITOS!K:K)} -> Adulto | M35: Asistió | N35: Asistió | O35: Asistió | P35: Asistió | Q35: Asistió | X35: =(COUNTIF(M35:W35, "Asistió")+COUNTIF(M35:W35, "Asíncrono")) -> 5 | Y35: TRUE
A36: SS_1 | B36: {=XLOOKUP(A36, CURSOS!A:A, CURSOS!B:B)} -> 4 | C36: {=XLOOKUP(A36, CURSOS!A:A, CURSOS!C:C)} -> VAGABUNDOS DEL FIRMAMENTO | D36: P0029 | E36: {=XLOOKUP($D36,REGOLITOS!$A:$A,REGOLITOS!E:E)} -> 15 | F36: {=XLOOKUP($D36,REGOLITOS!$A:$A,REGOLITOS!F:F)} -> Ingeniería Civil | G36: {=XLOOKUP($D36,REGOLITOS!$A:$A,REGOLITOS!G:G)} -> Ciudad de México | H36: {=XLOOKUP($D36,REGOLITOS!$A:$A,REGOLITOS!H:H)} -> 55 55 0028 0028 | I36: {=XLOOKUP($D36,REGOLITOS!$A:$A,REGOLITOS!I:I)} -> usuario28@ejemplo.com | J36: {=XLOOKUP($D36,REGOLITOS!$A:$A,REGOLITOS!J:J)} -> Tutor_028 | K36: {=XLOOKUP($D36,REGOLITOS!$A:$A,REGOLITOS!K:K)} -> Adolescente | L36: 160 | M36: Asistió | N36: Asistió | O36: Asistió | P36: Asistió | Q36: Asistió | X36: =(COUNTIF(M36:W36, "Asistió")+COUNTIF(M36:W36, "Asíncrono")) -> 5 | Y36: TRUE
A37: SS_1 | B37: {=XLOOKUP(A37, CURSOS!A:A, CURSOS!B:B)} -> 4 | C37: {=XLOOKUP(A37, CURSOS!A:A, CURSOS!C:C)} -> VAGABUNDOS DEL FIRMAMENTO | D37: P0086 | E37: {=XLOOKUP($D37,REGOLITOS!$A:$A,REGOLITOS!E:E)} -> 18 | F37: {=XLOOKUP($D37,REGOLITOS!$A:$A,REGOLITOS!F:F)} -> Estudiante | G37: {=XLOOKUP($D37,REGOLITOS!$A:$A,REGOLITOS!G:G)} -> Hidalgo | H37: {=XLOOKUP($D37,REGOLITOS!$A:$A,REGOLITOS!H:H)} -> 55 55 0085 0085 | I37: {=XLOOKUP($D37,REGOLITOS!$A:$A,REGOLITOS!I:I)} -> usuario85@ejemplo.com | J37: {=XLOOKUP($D37,REGOLITOS!$A:$A,REGOLITOS!J:J)} -> Tutor_085 | K37: {=XLOOKUP($D37,REGOLITOS!$A:$A,REGOLITOS!K:K)} -> Jóven adulto | L37: 160 | M37: Asistió | N37: Asistió | O37: Asistió | P37: Asistió | Q37: Asistió | X37: =(COUNTIF(M37:W37, "Asistió")+COUNTIF(M37:W37, "Asíncrono")) -> 5 | Y37: TRUE
A38: SS_1 | B38: {=XLOOKUP(A38, CURSOS!A:A, CURSOS!B:B)} -> 4 | C38: {=XLOOKUP(A38, CURSOS!A:A, CURSOS!C:C)} -> VAGABUNDOS DEL FIRMAMENTO | D38: P0083 | E38: {=XLOOKUP($D38,REGOLITOS!$A:$A,REGOLITOS!E:E)} -> 66 | F38: {=XLOOKUP($D38,REGOLITOS!$A:$A,REGOLITOS!F:F)} -> Operadora de CTP | G38: {=XLOOKUP($D38,REGOLITOS!$A:$A,REGOLITOS!G:G)} -> Ciudad de México | H38: {=XLOOKUP($D38,REGOLITOS!$A:$A,REGOLITOS!H:H)} -> 55 55 0082 0082 | I38: {=XLOOKUP($D38,REGOLITOS!$A:$A,REGOLITOS!I:I)} -> usuario82@ejemplo.com | J38: {=XLOOKUP($D38,REGOLITOS!$A:$A,REGOLITOS!J:J)} | K38: {=XLOOKUP($D38,REGOLITOS!$A:$A,REGOLITOS!K:K)} -> Adulto Mayor | M38: Asistió | N38: Asistió | O38: Asistió | P38: Asistió | Q38: Asistió | X38: =(COUNTIF(M38:W38, "Asistió")+COUNTIF(M38:W38, "Asíncrono")) -> 5 | Y38: TRUE
A39: SS_1 | B39: {=XLOOKUP(A39, CURSOS!A:A, CURSOS!B:B)} -> 4 | C39: {=XLOOKUP(A39, CURSOS!A:A, CURSOS!C:C)} -> VAGABUNDOS DEL FIRMAMENTO | D39: P0140 | E39: {=XLOOKUP($D39,REGOLITOS!$A:$A,REGOLITOS!E:E)} -> 23 | F39: {=XLOOKUP($D39,REGOLITOS!$A:$A,REGOLITOS!F:F)} -> Estudiante | G39: {=XLOOKUP($D39,REGOLITOS!$A:$A,REGOLITOS!G:G)} -> Desconocido | H39: {=XLOOKUP($D39,REGOLITOS!$A:$A,REGOLITOS!H:H)} -> 55 55 0139 0139 | I39: {=XLOOKUP($D39,REGOLITOS!$A:$A,REGOLITOS!I:I)} -> usuario139@ejemplo.com | J39: {=XLOOKUP($D39,REGOLITOS!$A:$A,REGOLITOS!J:J)} | K39: {=XLOOKUP($D39,REGOLITOS!$A:$A,REGOLITOS!K:K)} -> Jóven adulto | M39: Asistió | N39: Asistió | O39: Asistió | P39: Asíncrono | Q39: Asistió | X39: =(COUNTIF(M39:W39, "Asistió")+COUNTIF(M39:W39, "Asíncrono")) -> 5 | Y39: TRUE
A40: SS_1 | B40: {=XLOOKUP(A40, CURSOS!A:A, CURSOS!B:B)} -> 4 | C40: {=XLOOKUP(A40, CURSOS!A:A, CURSOS!C:C)} -> VAGABUNDOS DEL FIRMAMENTO | D40: P0129 | E40: {=XLOOKUP($D40,REGOLITOS!$A:$A,REGOLITOS!E:E)} -> 46 | F40: {=XLOOKUP($D40,REGOLITOS!$A:$A,REGOLITOS!F:F)} -> Administración | G40: {=XLOOKUP($D40,REGOLITOS!$A:$A,REGOLITOS!G:G)} -> Ciudad de México | H40: {=XLOOKUP($D40,REGOLITOS!$A:$A,REGOLITOS!H:H)} -> 55 55 0128 0128 | I40: {=XLOOKUP($D40,REGOLITOS!$A:$A,REGOLITOS!I:I)} -> usuario128@ejemplo.com | J40: {=XLOOKUP($D40,REGOLITOS!$A:$A,REGOLITOS!J:J)} | K40: {=XLOOKUP($D40,REGOLITOS!$A:$A,REGOLITOS!K:K)} -> Adulto | L40: 160 | M40: Asistió | N40: Faltó | O40: Asistió | P40: Asistió | Q40: Asistió | X40: =(COUNTIF(M40:W40, "Asistió")+COUNTIF(M40:W40, "Asíncrono")) -> 4 | Y40: TRUE
A41: SS_1 | B41: {=XLOOKUP(A41, CURSOS!A:A, CURSOS!B:B)} -> 4 | C41: {=XLOOKUP(A41, CURSOS!A:A, CURSOS!C:C)} -> VAGABUNDOS DEL FIRMAMENTO | D41: P0104 | E41: {=XLOOKUP($D41,REGOLITOS!$A:$A,REGOLITOS!E:E)} -> 66 | F41: {=XLOOKUP($D41,REGOLITOS!$A:$A,REGOLITOS!F:F)} -> Estudiante HS | G41: {=XLOOKUP($D41,REGOLITOS!$A:$A,REGOLITOS!G:G)} -> Jalisco | H41: {=XLOOKUP($D41,REGOLITOS!$A:$A,REGOLITOS!H:H)} -> 55 55 0103 0103 | I41: {=XLOOKUP($D41,REGOLITOS!$A:$A,REGOLITOS!I:I)} -> usuario103@ejemplo.com | J41: {=XLOOKUP($D41,REGOLITOS!$A:$A,REGOLITOS!J:J)} | K41: {=XLOOKUP($D41,REGOLITOS!$A:$A,REGOLITOS!K:K)} -> Adulto Mayor | L41: 160 | M41: Asistió | N41: Asistió | O41: Faltó | P41: Asistió | Q41: Asistió | X41: =(COUNTIF(M41:W41, "Asistió")+COUNTIF(M41:W41, "Asíncrono")) -> 4 | Y41: TRUE
A42: SS_1 | B42: {=XLOOKUP(A42, CURSOS!A:A, CURSOS!B:B)} -> 4 | C42: {=XLOOKUP(A42, CURSOS!A:A, CURSOS!C:C)} -> VAGABUNDOS DEL FIRMAMENTO | D42: P0088 | E42: {=XLOOKUP($D42,REGOLITOS!$A:$A,REGOLITOS!E:E)} -> 88 | F42: {=XLOOKUP($D42,REGOLITOS!$A:$A,REGOLITOS!F:F)} -> Desconocido | G42: {=XLOOKUP($D42,REGOLITOS!$A:$A,REGOLITOS!G:G)} -> Ciudad de México | H42: {=XLOOKUP($D42,REGOLITOS!$A:$A,REGOLITOS!H:H)} -> 55 55 0087 0087 | I42: {=XLOOKUP($D42,REGOLITOS!$A:$A,REGOLITOS!I:I)} -> usuario87@ejemplo.com | J42: {=XLOOKUP($D42,REGOLITOS!$A:$A,REGOLITOS!J:J)} | K42: {=XLOOKUP($D42,REGOLITOS!$A:$A,REGOLITOS!K:K)} -> Adulto Mayor | M42: Asistió | N42: Faltó | O42: Asistió | P42: Asistió | Q42: Asistió | X42: =(COUNTIF(M42:W42, "Asistió")+COUNTIF(M42:W42, "Asíncrono")) -> 4 | Y42: TRUE
A43: SS_1 | B43: {=XLOOKUP(A43, CURSOS!A:A, CURSOS!B:B)} -> 4 | C43: {=XLOOKUP(A43, CURSOS!A:A, CURSOS!C:C)} -> VAGABUNDOS DEL FIRMAMENTO | D43: P0124 | E43: {=XLOOKUP($D43,REGOLITOS!$A:$A,REGOLITOS!E:E)} -> 83 | F43: {=XLOOKUP($D43,REGOLITOS!$A:$A,REGOLITOS!F:F)} -> Desconocido | G43: {=XLOOKUP($D43,REGOLITOS!$A:$A,REGOLITOS!G:G)} -> Desconocido | H43: {=XLOOKUP($D43,REGOLITOS!$A:$A,REGOLITOS!H:H)} -> 55 55 0123 0123 | I43: {=XLOOKUP($D43,REGOLITOS!$A:$A,REGOLITOS!I:I)} -> usuario123@ejemplo.com | J43: {=XLOOKUP($D43,REGOLITOS!$A:$A,REGOLITOS!J:J)} | K43: {=XLOOKUP($D43,REGOLITOS!$A:$A,REGOLITOS!K:K)} -> Adulto Mayor | M43: Asistió | N43: Asistió | O43: Faltó | P43: Asistió | Q43: Faltó | X43: =(COUNTIF(M43:W43, "Asistió")+COUNTIF(M43:W43, "Asíncrono")) -> 3 | Y43: FALSE
A44: SS_1 | B44: {=XLOOKUP(A44, CURSOS!A:A, CURSOS!B:B)} -> 4 | C44: {=XLOOKUP(A44, CURSOS!A:A, CURSOS!C:C)} -> VAGABUNDOS DEL FIRMAMENTO | D44: P0032 | E44: {=XLOOKUP($D44,REGOLITOS!$A:$A,REGOLITOS!E:E)} -> 50 | F44: {=XLOOKUP($D44,REGOLITOS!$A:$A,REGOLITOS!F:F)} -> Estudiante | G44: {=XLOOKUP($D44,REGOLITOS!$A:$A,REGOLITOS!G:G)} -> Desconocido | H44: {=XLOOKUP($D44,REGOLITOS!$A:$A,REGOLITOS!H:H)} -> 55 55 0031 0031 | I44: {=XLOOKUP($D44,REGOLITOS!$A:$A,REGOLITOS!I:I)} -> usuario31@ejemplo.com | J44: {=XLOOKUP($D44,REGOLITOS!$A:$A,REGOLITOS!J:J)} | K44: {=XLOOKUP($D44,REGOLITOS!$A:$A,REGOLITOS!K:K)} -> Infancia | M44: Asistió | N44: Asistió | O44: Faltó | P44: Asistió | Q44: Faltó | X44: =(COUNTIF(M44:W44, "Asistió")+COUNTIF(M44:W44, "Asíncrono")) -> 3 | Y44: FALSE
